Workbook

Sheet 안내
A1: 투자 판단 보조 시트
A2: 판단 기준 명세(docs/spec.md)를 스프레드시트 수식으로 옮긴 1차 구현. 프로그램은 제안만 한다. 매매는 사람이 승인하고 직접 한다.
A4: 칸 색
A5: 노란 바탕 + 파란 글씨 = 입력하는 칸. 나머지는 수식이므로 고치지 않는다. 숨긴 열은 중간 계산이다(열 숨기기 해제로 볼 수 있음).
A7: 쓰는 순서
A8: 1. 종목_한국 / 종목_미국: 보유 종목과 후보의 재무·주가를 넣는다. → 거름망, 점수, 판정, 점수 설명 카드가 나온다.
A9: 2. 매수이유: 보유 종목과 살 종목의 이유(1~3개, 핵심 1개), 근거, 무너짐 기준, 점검 결과를 적는다.
A10: 3. 보유: 계좌 평가액, 대기 현금, 환율, 보유 종목을 넣는다. → 손실 한도·매도 판단을 우선순위대로 제안한다.
A11: 4. 자료_미국심리 / 자료_한국심리: 지표 원자료를 붙여 넣는다. → 심리_미국 / 심리_한국에서 점수와 분할 매수 방법이 나온다.
A12: 5. 매수계획: 새로 살 종목과 금액, 시작일을 넣는다. → 몇 회, 몇 주 간격, 1회 금액, 회차별 날짜가 나온다.
A13: 6. 자료_거시: FRED 원자료를 붙여 넣는다. → 거시 탭에 현재값과 10년 백분위가 표시된다(규칙에는 쓰지 않음).
A14: 7. 대시보드에서 한눈에 본다. 결정을 내리면 판단기록에 한 줄 남긴다.
... A33: 이 파일은 가상 데이터로 채운 예시다. 종목·숫자·원자료는 모두 지어낸 값이다. 실제로 쓸 때는 빈 양식(투자판단.xlsx)을 쓴다.

Sheet 대시보드
A1: 대시보드
A2: 프로그램은 제안만 한다. 매매는 사람이 승인하고 직접 한다. 자동 매매 없음.
A4: 시장 심리 — 신규 종목 매수 분할에만 사용
A5: 시장 | B5: 점수 | C5: 구간 | D5: 신규 매수 | E5: 기준일 | F5: 점검
A6: 미국 | B6: ='심리_미국'!$B$6 | C6: ='심리_미국'!$B$7 | D6: ='심리_미국'!$B$8 | E6: ='심리_미국'!$B$4 | F6: ='심리_미국'!$B$10
A7: 한국 | B7: ='심리_한국'!$B$6 | C7: ='심리_한국'!$B$7 | D7: ='심리_한국'!$B$8 | E7: ='심리_한국'!$B$4 | F7: ='심리_한국'!$B$10
A9: 보유 종목 제안 — 우선순위 ① 손실 한도 ② 핵심 이유 붕괴 ③ 비중 초과 ④ 교체
A10: 국가 | B10: 종목코드 | C10: 종목명 | D10: 최종 제안 | E10: 점수 | F10: 매수 이유 기록 | G10: 실적 점검
A11: =IF('보유'!$B11="","",'보유'!A11&"") | B11: =IF('보유'!$B11="","",'보유'!B11&"") | C11: =IF('보유'!$B11="","",'보유'!C11&"") | D11: =IF('보유'!$B11="","",'보유'!I11) | E11: =IF('보유'!$B11="","",'보유'!U11) | F11: =IF('보유'!$B11="","",'보유'!O11) | G11: =IF('보유'!$B11="","",'보유'!Q11)
A12: =IF('보유'!$B12="","",'보유'!A12&"") | B12: =IF('보유'!$B12="","",'보유'!B12&"") | C12: =IF('보유'!$B12="","",'보유'!C12&"") | D12: =IF('보유'!$B12="","",'보유'!I12) | E12: =IF('보유'!$B12="","",'보유'!U12) | F12: =IF('보유'!$B12="","",'보유'!O12) | G12: =IF('보유'!$B12="","",'보유'!Q12)
A13: =IF('보유'!$B13="","",'보유'!A13&"") | B13: =IF('보유'!$B13="","",'보유'!B13&"") | C13: =IF('보유'!$B13="","",'보유'!C13&"") | D13: =IF('보유'!$B13="","",'보유'!I13) | E13: =IF('보유'!$B13="","",'보유'!U13) | F13: =IF('보유'!$B13="","",'보유'!O13) | G13: =IF('보유'!$B13="","",'보유'!Q13)
A14: =IF('보유'!$B14="","",'보유'!A14&"") | B14: =IF('보유'!$B14="","",'보유'!B14&"") | C14: =IF('보유'!$B14="","",'보유'!C14&"") | D14: =IF('보유'!$B14="","",'보유'!I14) | E14: =IF('보유'!$B14="","",'보유'!U14) | F14: =IF('보유'!$B14="","",'보유'!O14) | G14: =IF('보유'!$B14="","",'보유'!Q14)
A15: =IF('보유'!$B15="","",'보유'!A15&"") | B15: =IF('보유'!$B15="","",'보유'!B15&"") | C15: =IF('보유'!$B15="","",'보유'!C15&"") | D15: =IF('보유'!$B15="","",'보유'!I15) | E15: =IF('보유'!$B15="","",'보유'!U15) | F15: =IF('보유'!$B15="","",'보유'!O15) | G15: =IF('보유'!$B15="","",'보유'!Q15)
A16: =IF('보유'!$B16="","",'보유'!A16&"") | B16: =IF('보유'!$B16="","",'보유'!B16&"") | C16: =IF('보유'!$B16="","",'보유'!C16&"") | D16: =IF('보유'!$B16="","",'보유'!I16) | E16: =IF('보유'!$B16="","",'보유'!U16) | F16: =IF('보유'!$B16="","",'보유'!O16) | G16: =IF('보유'!$B16="","",'보유'!Q16)
A17: =IF('보유'!$B17="","",'보유'!A17&"") | B17: =IF('보유'!$B17="","",'보유'!B17&"") | C17: =IF('보유'!$B17="","",'보유'!C17&"") | D17: =IF('보유'!$B17="","",'보유'!I17) | E17: =IF('보유'!$B17="","",'보유'!U17) | F17: =IF('보유'!$B17="","",'보유'!O17) | G17: =IF('보유'!$B17="","",'보유'!Q17)
A18: =IF('보유'!$B18="","",'보유'!A18&"") | B18: =IF('보유'!$B18="","",'보유'!B18&"") | C18: =IF('보유'!$B18="","",'보유'!C18&"") | D18: =IF('보유'!$B18="","",'보유'!I18) | E18: =IF('보유'!$B18="","",'보유'!U18) | F18: =IF('보유'!$B18="","",'보유'!O18) | G18: =IF('보유'!$B18="","",'보유'!Q18)
A19: =IF('보유'!$B19="","",'보유'!A19&"") | B19: =IF('보유'!$B19="","",'보유'!B19&"") | C19: =IF('보유'!$B19="","",'보유'!C19&"") | D19: =IF('보유'!$B19="","",'보유'!I19) | E19: =IF('보유'!$B19="","",'보유'!U19) | F19: =IF('보유'!$B19="","",'보유'!O19) | G19: =IF('보유'!$B19="","",'보유'!Q19)
A20: =IF('보유'!$B20="","",'보유'!A20&"") | B20: =IF('보유'!$B20="","",'보유'!B20&"") | C20: =IF('보유'!$B20="","",'보유'!C20&"") | D20: =IF('보유'!$B20="","",'보유'!I20) | E20: =IF('보유'!$B20="","",'보유'!U20) | F20: =IF('보유'!$B20="","",'보유'!O20) | G20: =IF('보유'!$B20="","",'보유'!Q20)
A22: 편입 후보 — 점수 70 이상, 미보유 (점수순)
A23: 순위 | B23: 점수 | C23: 한국 종목 | D23: 한 줄 요약 | E23: 점수 | F23: 미국 종목 | G23: 한 줄 요약
A24: 1 | B24: =IFERROR(INDEX('종목_한국'!$R$6:$R$105,MATCH(LARGE('종목_한국'!$AQ$6:$AQ$105,1),'종목_한국'!$AQ$6:$AQ$105,0)),"") | C24: =IFERROR(INDEX('종목_한국'!$B$6:$B$105,MATCH(LARGE('종목_한국'!$AQ$6:$AQ$105,1),'종목_한국'!$AQ$6:$AQ$105,0))&"","") | D24: =IFERROR(INDEX('종목_한국'!$S$6:$S$105,MATCH(LARGE('종목_한국'!$AQ$6:$AQ$105,1),'종목_한국'!$AQ$6:$AQ$105,0))&"","") | E24: =IFERROR(INDEX('종목_미국'!$R$6:$R$105,MATCH(LARGE('종목_미국'!$AQ$6:$AQ$105,1),'종목_미국'!$AQ$6:$AQ$105,0)),"") | F24: =IFERROR(INDEX('종목_미국'!$B$6:$B$105,MATCH(LARGE('종목_미국'!$AQ$6:$AQ$105,1),'종목_미국'!$AQ$6:$AQ$105,0))&"","") | G24: =IFERROR(INDEX('종목_미국'!$S$6:$S$105,MATCH(LARGE('종목_미국'!$AQ$6:$AQ$105,1),'종목_미국'!$AQ$6:$AQ$105,0))&"","")
A25: 2 | B25: =IFERROR(INDEX('종목_한국'!$R$6:$R$105,MATCH(LARGE('종목_한국'!$AQ$6:$AQ$105,2),'종목_한국'!$AQ$6:$AQ$105,0)),"") | C25: =IFERROR(INDEX('종목_한국'!$B$6:$B$105,MATCH(LARGE('종목_한국'!$AQ$6:$AQ$105,2),'종목_한국'!$AQ$6:$AQ$105,0))&"","") | D25: =IFERROR(INDEX('종목_한국'!$S$6:$S$105,MATCH(LARGE('종목_한국'!$AQ$6:$AQ$105,2),'종목_한국'!$AQ$6:$AQ$105,0))&"","") | E25: =IFERROR(INDEX('종목_미국'!$R$6:$R$105,MATCH(LARGE('종목_미국'!$AQ$6:$AQ$105,2),'종목_미국'!$AQ$6:$AQ$105,0)),"") | F25: =IFERROR(INDEX('종목_미국'!$B$6:$B$105,MATCH(LARGE('종목_미국'!$AQ$6:$AQ$105,2),'종목_미국'!$AQ$6:$AQ$105,0))&"","") | G25: =IFERROR(INDEX('종목_미국'!$S$6:$S$105,MATCH(LARGE('종목_미국'!$AQ$6:$AQ$105,2),'종목_미국'!$AQ$6:$AQ$105,0))&"","")
A26: 3 | B26: =IFERROR(INDEX('종목_한국'!$R$6:$R$105,MATCH(LARGE('종목_한국'!$AQ$6:$AQ$105,3),'종목_한국'!$AQ$6:$AQ$105,0)),"") | C26: =IFERROR(INDEX('종목_한국'!$B$6:$B$105,MATCH(LARGE('종목_한국'!$AQ$6:$AQ$105,3),'종목_한국'!$AQ$6:$AQ$105,0))&"","") | D26: =IFERROR(INDEX('종목_한국'!$S$6:$S$105,MATCH(LARGE('종목_한국'!$AQ$6:$AQ$105,3),'종목_한국'!$AQ$6:$AQ$105,0))&"","") | E26: =IFERROR(INDEX('종목_미국'!$R$6:$R$105,MATCH(LARGE('종목_미국'!$AQ$6:$AQ$105,3),'종목_미국'!$AQ$6:$AQ$105,0)),"") | F26: =IFERROR(INDEX('종목_미국'!$B$6:$B$105,MATCH(LARGE('종목_미국'!$AQ$6:$AQ$105,3),'종목_미국'!$AQ$6:$AQ$105,0))&"","") | G26: =IFERROR(INDEX('종목_미국'!$S$6:$S$105,MATCH(LARGE('종목_미국'!$AQ$6:$AQ$105,3),'종목_미국'!$AQ$6:$AQ$105,0))&"","")
A27: 4 | B27: =IFERROR(INDEX('종목_한국'!$R$6:$R$105,MATCH(LARGE('종목_한국'!$AQ$6:$AQ$105,4),'종목_한국'!$AQ$6:$AQ$105,0)),"") | C27: =IFERROR(INDEX('종목_한국'!$B$6:$B$105,MATCH(LARGE('종목_한국'!$AQ$6:$AQ$105,4),'종목_한국'!$AQ$6:$AQ$105,0))&"","") | D27: =IFERROR(INDEX('종목_한국'!$S$6:$S$105,MATCH(LARGE('종목_한국'!$AQ$6:$AQ$105,4),'종목_한국'!$AQ$6:$AQ$105,0))&"","") | E27: =IFERROR(INDEX('종목_미국'!$R$6:$R$105,MATCH(LARGE('종목_미국'!$AQ$6:$AQ$105,4),'종목_미국'!$AQ$6:$AQ$105,0)),"") | F27: =IFERROR(INDEX('종목_미국'!$B$6:$B$105,MATCH(LARGE('종목_미국'!$AQ$6:$AQ$105,4),'종목_미국'!$AQ$6:$AQ$105,0))&"","") | G27: =IFERROR(INDEX('종목_미국'!$S$6:$S$105,MATCH(LARGE('종목_미국'!$AQ$6:$AQ$105,4),'종목_미국'!$AQ$6:$AQ$105,0))&"","")
A28: 5 | B28: =IFERROR(INDEX('종목_한국'!$R$6:$R$105,MATCH(LARGE('종목_한국'!$AQ$6:$AQ$105,5),'종목_한국'!$AQ$6:$AQ$105,0)),"") | C28: =IFERROR(INDEX('종목_한국'!$B$6:$B$105,MATCH(LARGE('종목_한국'!$AQ$6:$AQ$105,5),'종목_한국'!$AQ$6:$AQ$105,0))&"","") | D28: =IFERROR(INDEX('종목_한국'!$S$6:$S$105,MATCH(LARGE('종목_한국'!$AQ$6:$AQ$105,5),'종목_한국'!$AQ$6:$AQ$105,0))&"","") | E28: =IFERROR(INDEX('종목_미국'!$R$6:$R$105,MATCH(LARGE('종목_미국'!$AQ$6:$AQ$105,5),'종목_미국'!$AQ$6:$AQ$105,0)),"") | F28: =IFERROR(INDEX('종목_미국'!$B$6:$B$105,MATCH(LARGE('종목_미국'!$AQ$6:$AQ$105,5),'종목_미국'!$AQ$6:$AQ$105,0))&"","") | G28: =IFERROR(INDEX('종목_미국'!$S$6:$S$105,MATCH(LARGE('종목_미국'!$AQ$6:$AQ$105,5),'종목_미국'!$AQ$6:$AQ$105,0))&"","")
A29: 6 | B29: =IFERROR(INDEX('종목_한국'!$R$6:$R$105,MATCH(LARGE('종목_한국'!$AQ$6:$AQ$105,6),'종목_한국'!$AQ$6:$AQ$105,0)),"") | C29: =IFERROR(INDEX('종목_한국'!$B$6:$B$105,MATCH(LARGE('종목_한국'!$AQ$6:$AQ$105,6),'종목_한국'!$AQ$6:$AQ$105,0))&"","") | D29: =IFERROR(INDEX('종목_한국'!$S$6:$S$105,MATCH(LARGE('종목_한국'!$AQ$6:$AQ$105,6),'종목_한국'!$AQ$6:$AQ$105,0))&"","") | E29: =IFERROR(INDEX('종목_미국'!$R$6:$R$105,MATCH(LARGE('종목_미국'!$AQ$6:$AQ$105,6),'종목_미국'!$AQ$6:$AQ$105,0)),"") | F29: =IFERROR(INDEX('종목_미국'!$B$6:$B$105,MATCH(LARGE('종목_미국'!$AQ$6:$AQ$105,6),'종목_미국'!$AQ$6:$AQ$105,0))&"","") | G29: =IFERROR(INDEX('종목_미국'!$S$6:$S$105,MATCH(LARGE('종목_미국'!$AQ$6:$AQ$105,6),'종목_미국'!$AQ$6:$AQ$105,0))&"","")
A30: 7 | B30: =IFERROR(INDEX('종목_한국'!$R$6:$R$105,MATCH(LARGE('종목_한국'!$AQ$6:$AQ$105,7),'종목_한국'!$AQ$6:$AQ$105,0)),"") | C30: =IFERROR(INDEX('종목_한국'!$B$6:$B$105,MATCH(LARGE('종목_한국'!$AQ$6:$AQ$105,7),'종목_한국'!$AQ$6:$AQ$105,0))&"","") | D30: =IFERROR(INDEX('종목_한국'!$S$6:$S$105,MATCH(LARGE('종목_한국'!$AQ$6:$AQ$105,7),'종목_한국'!$AQ$6:$AQ$105,0))&"","") | E30: =IFERROR(INDEX('종목_미국'!$R$6:$R$105,MATCH(LARGE('종목_미국'!$AQ$6:$AQ$105,7),'종목_미국'!$AQ$6:$AQ$105,0)),"") | F30: =IFERROR(INDEX('종목_미국'!$B$6:$B$105,MATCH(LARGE('종목_미국'!$AQ$6:$AQ$105,7),'종목_미국'!$AQ$6:$AQ$105,0))&"","") | G30: =IFERROR(INDEX('종목_미국'!$S$6:$S$105,MATCH(LARGE('종목_미국'!$AQ$6:$AQ$105,7),'종목_미국'!$AQ$6:$AQ$105,0))&"","")
A31: 8 | B31: =IFERROR(INDEX('종목_한국'!$R$6:$R$105,MATCH(LARGE('종목_한국'!$AQ$6:$AQ$105,8),'종목_한국'!$AQ$6:$AQ$105,0)),"") | C31: =IFERROR(INDEX('종목_한국'!$B$6:$B$105,MATCH(LARGE('종목_한국'!$AQ$6:$AQ$105,8),'종목_한국'!$AQ$6:$AQ$105,0))&"","") | D31: =IFERROR(INDEX('종목_한국'!$S$6:$S$105,MATCH(LARGE('종목_한국'!$AQ$6:$AQ$105,8),'종목_한국'!$AQ$6:$AQ$105,0))&"","") | E31: =IFERROR(INDEX('종목_미국'!$R$6:$R$105,MATCH(LARGE('종목_미국'!$AQ$6:$AQ$105,8),'종목_미국'!$AQ$6:$AQ$105,0)),"") | F31: =IFERROR(INDEX('종목_미국'!$B$6:$B$105,MATCH(LARGE('종목_미국'!$AQ$6:$AQ$105,8),'종목_미국'!$AQ$6:$AQ$105,0))&"","") | G31: =IFERROR(INDEX('종목_미국'!$S$6:$S$105,MATCH(LARGE('종목_미국'!$AQ$6:$AQ$105,8),'종목_미국'!$AQ$6:$AQ$105,0))&"","")
A32: 9 | B32: =IFERROR(INDEX('종목_한국'!$R$6:$R$105,MATCH(LARGE('종목_한국'!$AQ$6:$AQ$105,9),'종목_한국'!$AQ$6:$AQ$105,0)),"") | C32: =IFERROR(INDEX('종목_한국'!$B$6:$B$105,MATCH(LARGE('종목_한국'!$AQ$6:$AQ$105,9),'종목_한국'!$AQ$6:$AQ$105,0))&"","") | D32: =IFERROR(INDEX('종목_한국'!$S$6:$S$105,MATCH(LARGE('종목_한국'!$AQ$6:$AQ$105,9),'종목_한국'!$AQ$6:$AQ$105,0))&"","") | E32: =IFERROR(INDEX('종목_미국'!$R$6:$R$105,MATCH(LARGE('종목_미국'!$AQ$6:$AQ$105,9),'종목_미국'!$AQ$6:$AQ$105,0)),"") | F32: =IFERROR(INDEX('종목_미국'!$B$6:$B$105,MATCH(LARGE('종목_미국'!$AQ$6:$AQ$105,9),'종목_미국'!$AQ$6:$AQ$105,0))&"","") | G32: =IFERROR(INDEX('종목_미국'!$S$6:$S$105,MATCH(LARGE('종목_미국'!$AQ$6:$AQ$105,9),'종목_미국'!$AQ$6:$AQ$105,0))&"","")
A33: 10 | B33: =IFERROR(INDEX('종목_한국'!$R$6:$R$105,MATCH(LARGE('종목_한국'!$AQ$6:$AQ$105,10),'종목_한국'!$AQ$6:$AQ$105,0)),"") | C33: =IFERROR(INDEX('종목_한국'!$B$6:$B$105,MATCH(LARGE('종목_한국'!$AQ$6:$AQ$105,10),'종목_한국'!$AQ$6:$AQ$105,0))&"","") | D33: =IFERROR(INDEX('종목_한국'!$S$6:$S$105,MATCH(LARGE('종목_한국'!$AQ$6:$AQ$105,10),'종목_한국'!$AQ$6:$AQ$105,0))&"","") | E33: =IFERROR(INDEX('종목_미국'!$R$6:$R$105,MATCH(LARGE('종목_미국'!$AQ$6:$AQ$105,10),'종목_미국'!$AQ$6:$AQ$105,0)),"") | F33: =IFERROR(INDEX('종목_미국'!$B$6:$B$105,MATCH(LARGE('종목_미국'!$AQ$6:$AQ$105,10),'종목_미국'!$AQ$6:$AQ$105,0))&"","") | G33: =IFERROR(INDEX('종목_미국'!$S$6:$S$105,MATCH(LARGE('종목_미국'!$AQ$6:$AQ$105,10),'종목_미국'!$AQ$6:$AQ$105,0))&"","")
A35: 거시 참고 패널 — 표시만, 어떤 규칙에도 쓰지 않음
A36: 지표 | D36: 보는 것 | E36: 현재값 | F36: 10년 백분위 | G36: 기준일 · 점검
A37: ='거시'!A5 | D37: ='거시'!B5 | E37: ='거시'!C5 | F37: ='거시'!F5 | G37: =IF('거시'!E5="",'거시'!J5,TEXT('거시'!E5,"yyyy-mm-dd")&" · "&'거시'!J5)
A38: ='거시'!A6 | D38: ='거시'!B6 | E38: ='거시'!C6 | F38: ='거시'!F6 | G38: =IF('거시'!E6="",'거시'!J6,TEXT('거시'!E6,"yyyy-mm-dd")&" · "&'거시'!J6)
A39: ='거시'!A7 | D39: ='거시'!B7 | E39: ='거시'!C7 | F39: ='거시'!F7 | G39: =IF('거시'!E7="",'거시'!J7,TEXT('거시'!E7,"yyyy-mm-dd")&" · "&'거시'!J7)
A40: ='거시'!A8 | D40: ='거시'!B8 | E40: ='거시'!C8 | F40: ='거시'!F8 | G40: =IF('거시'!E8="",'거시'!J8,TEXT('거시'!E8,"yyyy-mm-dd")&" · "&'거시'!J8)
A41: ='거시'!A9 | D41: ='거시'!B9 | E41: ='거시'!C9 | F41: ='거시'!F9 | G41: =IF('거시'!E9="",'거시'!J9,TEXT('거시'!E9,"yyyy-mm-dd")&" · "&'거시'!J9)

Sheet 종목_한국
A1: 종목 점수 — 한국
A2: 금액 단위: 억 원 · 주가: 원(수정주가) · 보유 종목과 후보를 모두 적는다. 순위는 이 시트(같은 국가) 안에서만 매긴다.
A3: 채점 종목 수 | B3: =COUNT($AF$6:$AF$105) | D3: 최고 미보유 후보 | E3: =IF(H3="","",INDEX($B$6:$B$105,MATCH(H3,$AP$6:$AP$105,0))&"") | G3: 점수 | H3: =IF(COUNT($AP$6:$AP$105)=0,"",MAX($AP$6:$AP$105)) | J3: 주가 기준일 | K3: 46295
A4: 입력 (노란 칸) | Q4: 결과 — 점수 설명 카드
A5: 종목코드 | B5: 종목명 | C5: 보유 (Y) | D5: 금융·리츠 (Y) | E5: 재무 기준 (메모) | F5: 순이익 최근 1년 | G5: 자본총계 | H5: 부채총계 | I5: 영업이익 최근 1년 | J5: 매출 최근 1년 | K5: 매출 3년 전 1년 | L5: 시가총액 | M5: 이자부부채 | N5: 현금성자산 | O5: 주가 12개월 전 | P5: 주가 1개월 전 | Q5: 판정 | R5: 점수 (0~100) | S5: 한 줄 요약 | T5: ROE 값 · 풀 안 위치 | U5: 매출성장률(3년 연평균) 값 · 풀 안 위치 | V5: 이익수익률 값 · 풀 안 위치 | W5: 12-1개월 수익률 값 · 풀 안 위치 | X5: 거름망 | Y5: 부채비율 | Z5: ROE | AA5: 매출성장률 | AB5: 이익수익률 | AC5: 12-1 수익률 | AD5: 결측 | AE5: 상태 | AF5: 채점(1) | AG5: ROE(채점) | AH5: 성장(채점) | AI5: 이익수익률(채점) | AJ5: 12-1(채점) | AK5: ROE 백분위 | AL5: 성장 백분위 | AM5: 이익수익률 백분위 | AN5: 12-1 백분위 | AO5: 평균 백분위 | AP5: 미보유 후보 점수 | AQ5: 대시보드 순위값 | AR5: 거름망 사유
A6: K01 | B6: 예시전자 | C6: Y | E6: 2026-2Q | F6: 1200 | G6: 8000 | H6: 4000 | I6: 1600 | J6: 12000 | K6: 8000 | L6: 15000 | M6: 1500 | N6: 2500 | O6: 50000 | P6: 62000 | Q6: =IF(A6="","",IF(C6="Y",IF(AF6=1,IF(AND(R6<'설정'!$B$6,ISNUMBER($H$3)),IF(ROUND($H$3-R6,1)>='설정'!$B$7,"교체 제안 → "&$E$3&" ("&TEXT($H$3,"0.0")&")","보유 유지"),"보유 유지"),"보유 · 점수 없음"),IF(AF6=1,IF(R6>='설정'!$B$5,"편입 후보",""),""))) | R6: =IF(AF6=1,ROUND(IF($B$3=1,50,(_xlfn.RANK.AVG(AO6,$AO$6:$AO$105,1)-1)/($B$3-1)*100),1),"") | S6: =IF(A6="","",IF(AF6=1,_xlfn.TEXTJOIN(". ",TRUE,_xlfn.TEXTJOIN(", ",TRUE,IF(AK6>='설정'!$B$20,"수익성 높음",""),IF(AL6>='설정'!$B$20,"성장 빠름",""),IF(AM6>='설정'!$B$20,"가격 쌈",""),IF(AN6>='설정'!$B$20,"추세 좋음","")),_xlfn.TEXTJOIN(", ",TRUE,IF(AK6<'설정'!$B$21,"수익성 낮음",""),IF(AL6<'설정'!$B$21,"성장 느림",""),IF(AM6<'설정'!$B$21,"가격 비쌈",""),IF(AN6<'설정'!$B$21,"추세 약함","")),IF(_xlfn.TEXTJOIN("·",TRUE,IF(AND(AK6>='설정'!$B$21,AK6<'설정'!$B$20),"수익성",""),IF(AND(AL6>='설정'!$B$21,AL6<'설정'!$B$20),"성장",""),IF(AND(AM6>='설정'!$B$21,AM6<'설정'!$B$20),"가격",""),IF(AND(AN6>='설정'!$B$21,AN6<'설정'!$B$20),"추세",""))="","","보통: "&_xlfn.TEXTJOIN("·",TRUE,IF(AND(AK6>='설정'!$B$21,AK6<'설정'!$B$20),"수익성",""),IF(AND(AL6>='설정'!$B$21,AL6<'설정'!$B$20),"성장",""),IF(AND(AM6>='설정'!$B$21,AM6<'설정'!$B$20),"가격",""),IF(AND(AN6>='설정'!$B$21,AN6<'설정'!$B$20),"추세","")))),IF(X6="통과",AE6,X6))) | T6: =IF(AF6=1,TEXT(Z6,"0.0%")&" · 상위 "&TEXT(($B$3-_xlfn.RANK.AVG(AG6,$AG$6:$AG$105,1)+1)/$B$3*100,"0")&"%",IF(A6="","",IF(Z6="","결측",TEXT(Z6,"0.0%")))) | U6: =IF(AF6=1,TEXT(AA6,"0.0%")&" · 상위 "&TEXT(($B$3-_xlfn.RANK.AVG(AH6,$AH$6:$AH$105,1)+1)/$B$3*100,"0")&"%",IF(A6="","",IF(AA6="","결측",TEXT(AA6,"0.0%")))) | V6: =IF(AF6=1,TEXT(AB6,"0.0%")&" · 상위 "&TEXT(($B$3-_xlfn.RANK.AVG(AI6,$AI$6:$AI$105,1)+1)/$B$3*100,"0")&"%",IF(A6="","",IF(AB6="","결측",TEXT(AB6,"0.0%")))) | W6: =IF(AF6=1,TEXT(AC6,"0.0%")&" · 상위 "&TEXT(($B$3-_xlfn.RANK.AVG(AJ6,$AJ$6:$AJ$105,1)+1)/$B$3*100,"0")&"%",IF(A6="","",IF(AC6="","결측",TEXT(AC6,"0.0%")))) | X6: =IF(A6="","",IF(AR6="","통과","제외: "&AR6)) | Y6: =IF(AND(ISNUMBER(G6),ISNUMBER(H6)),IF(G6>0,H6/G6,""),"") | Z6: =IF(AND(ISNUMBER(F6),ISNUMBER(G6)),IF(G6>0,F6/G6,""),"") | AA6: =IF(AND(ISNUMBER(J6),ISNUMBER(K6)),IF(AND(J6>0,K6>0),(J6/K6)^(1/3)-1,""),"") | AB6: =IF(AND(ISNUMBER(I6),ISNUMBER(L6),ISNUMBER(M6),ISNUMBER(N6)),IF((L6+M6-N6)>0,I6/(L6+M6-N6),""),"") | AC6: =IF(AND(ISNUMBER(O6),ISNUMBER(P6)),IF(AND(O6>0,P6>0),P6/O6-1,""),"") | AD6: =_xlfn.TEXTJOIN(", ",TRUE,IF(Z6="","ROE",""),IF(AA6="","매출성장률",""),IF(AB6="","이익수익률",""),IF(AC6="","12-1 수익률","")) | AE6: =IF(A6="","",IF(AR6<>"","점수 없음(거름망)",IF(AD6="","채점","점수 없음(결측: "&AD6&")"))) | AF6: =IF(AE6="채점",1,"") | AG6: =IF(AF6=1,Z6,"") | AH6: =IF(AF6=1,AA6,"") | AI6: =IF(AF6=1,AB6,"") | AJ6: =IF(AF6=1,AC6,"") | AK6: =IF(AF6=1,IF($B$3=1,50,(_xlfn.RANK.AVG(AG6,$AG$6:$AG$105,1)-1)/($B$3-1)*100),"") | AL6: =IF(AF6=1,IF($B$3=1,50,(_xlfn.RANK.AVG(AH6,$AH$6:$AH$105,1)-1)/($B$3-1)*100),"") | AM6: =IF(AF6=1,IF($B$3=1,50,(_xlfn.RANK.AVG(AI6,$AI$6:$AI$105,1)-1)/($B$3-1)*100),"") | AN6: =IF(AF6=1,IF($B$3=1,50,(_xlfn.RANK.AVG(AJ6,$AJ$6:$AJ$105,1)-1)/($B$3-1)*100),"") | AO6: =IF(AF6=1,ROUND(AVERAGE(AK6:AN6),6),"") | AP6: =IF(AND(AF6=1,C6<>"Y"),R6,"") | AQ6: =IF(AND(ISNUMBER(AP6),Q6="편입 후보"),AP6+(1000-ROW())/1000000,"") | AR6: =IF(A6="","",_xlfn.TEXTJOIN(", ",TRUE,IF(D6="Y","금융·리츠",""),IF(NOT(ISNUMBER(I6)),"영업이익 없음",IF(I6<=0,"영업적자","")),IF(OR(NOT(ISNUMBER(G6)),NOT(ISNUMBER(H6))),"부채비율 자료 없음",IF(G6<=0,"자본잠식",IF(H6/G6>'설정'!$B$8,"부채비율 초과",""))),IF(NOT(ISNUMBER(L6)),"시총 없음",IF(L6<'설정'!$B$9,"시총 미달",""))))
A7: K02 | B7: 예시화학 | C7: Y | E7: 2026-2Q | F7: 150 | G7: 9000 | H7: 9000 | I7: 300 | J7: 7000 | K7: 7500 | L7: 6000 | M7: 4000 | N7: 500 | O7: 30000 | P7: 24000 | Q7: =IF(A7="","",IF(C7="Y",IF(AF7=1,IF(AND(R7<'설정'!$B$6,ISNUMBER($H$3)),IF(ROUND($H$3-R7,1)>='설정'!$B$7,"교체 제안 → "&$E$3&" ("&TEXT($H$3,"0.0")&")","보유 유지"),"보유 유지"),"보유 · 점수 없음"),IF(AF7=1,IF(R7>='설정'!$B$5,"편입 후보",""),""))) | R7: =IF(AF7=1,ROUND(IF($B$3=1,50,(_xlfn.RANK.AVG(AO7,$AO$6:$AO$105,1)-1)/($B$3-1)*100),1),"") | S7: =IF(A7="","",IF(AF7=1,_xlfn.TEXTJOIN(". ",TRUE,_xlfn.TEXTJOIN(", ",TRUE,IF(AK7>='설정'!$B$20,"수익성 높음",""),IF(AL7>='설정'!$B$20,"성장 빠름",""),IF(AM7>='설정'!$B$20,"가격 쌈",""),IF(AN7>='설정'!$B$20,"추세 좋음","")),_xlfn.TEXTJOIN(", ",TRUE,IF(AK7<'설정'!$B$21,"수익성 낮음",""),IF(AL7<'설정'!$B$21,"성장 느림",""),IF(AM7<'설정'!$B$21,"가격 비쌈",""),IF(AN7<'설정'!$B$21,"추세 약함","")),IF(_xlfn.TEXTJOIN("·",TRUE,IF(AND(AK7>='설정'!$B$21,AK7<'설정'!$B$20),"수익성",""),IF(AND(AL7>='설정'!$B$21,AL7<'설정'!$B$20),"성장",""),IF(AND(AM7>='설정'!$B$21,AM7<'설정'!$B$20),"가격",""),IF(AND(AN7>='설정'!$B$21,AN7<'설정'!$B$20),"추세",""))="","","보통: "&_xlfn.TEXTJOIN("·",TRUE,IF(AND(AK7>='설정'!$B$21,AK7<'설정'!$B$20),"수익성",""),IF(AND(AL7>='설정'!$B$21,AL7<'설정'!$B$20),"성장",""),IF(AND(AM7>='설정'!$B$21,AM7<'설정'!$B$20),"가격",""),IF(AND(AN7>='설정'!$B$21,AN7<'설정'!$B$20),"추세","")))),IF(X7="통과",AE7,X7))) | T7: =IF(AF7=1,TEXT(Z7,"0.0%")&" · 상위 "&TEXT(($B$3-_xlfn.RANK.AVG(AG7,$AG$6:$AG$105,1)+1)/$B$3*100,"0")&"%",IF(A7="","",IF(Z7="","결측",TEXT(Z7,"0.0%")))) | U7: =IF(AF7=1,TEXT(AA7,"0.0%")&" · 상위 "&TEXT(($B$3-_xlfn.RANK.AVG(AH7,$AH$6:$AH$105,1)+1)/$B$3*100,"0")&"%",IF(A7="","",IF(AA7="","결측",TEXT(AA7,"0.0%")))) | V7: =IF(AF7=1,TEXT(AB7,"0.0%")&" · 상위 "&TEXT(($B$3-_xlfn.RANK.AVG(AI7,$AI$6:$AI$105,1)+1)/$B$3*100,"0")&"%",IF(A7="","",IF(AB7="","결측",TEXT(AB7,"0.0%")))) | W7: =IF(AF7=1,TEXT(AC7,"0.0%")&" · 상위 "&TEXT(($B$3-_xlfn.RANK.AVG(AJ7,$AJ$6:$AJ$105,1)+1)/$B$3*100,"0")&"%",IF(A7="","",IF(AC7="","결측",TEXT(AC7,"0.0%")))) | X7: =IF(A7="","",IF(AR7="","통과","제외: "&AR7)) | Y7: =IF(AND(ISNUMBER(G7),ISNUMBER(H7)),IF(G7>0,H7/G7,""),"") | Z7: =IF(AND(ISNUMBER(F7),ISNUMBER(G7)),IF(G7>0,F7/G7,""),"") | AA7: =IF(AND(ISNUMBER(J7),ISNUMBER(K7)),IF(AND(J7>0,K7>0),(J7/K7)^(1/3)-1,""),"") | AB7: =IF(AND(ISNUMBER(I7),ISNUMBER(L7),ISNUMBER(M7),ISNUMBER(N7)),IF((L7+M7-N7)>0,I7/(L7+M7-N7),""),"") | AC7: =IF(AND(ISNUMBER(O7),ISNUMBER(P7)),IF(AND(O7>0,P7>0),P7/O7-1,""),"") | AD7: =_xlfn.TEXTJOIN(", ",TRUE,IF(Z7="","ROE",""),IF(AA7="","매출성장률",""),IF(AB7="","이익수익률",""),IF(AC7="","12-1 수익률","")) | AE7: =IF(A7="","",IF(AR7<>"","점수 없음(거름망)",IF(AD7="","채점","점수 없음(결측: "&AD7&")"))) | AF7: =IF(AE7="채점",1,"") | AG7: =IF(AF7=1,Z7,"") | AH7: =IF(AF7=1,AA7,"") | AI7: =IF(AF7=1,AB7,"") | AJ7: =IF(AF7=1,AC7,"") | AK7: =IF(AF7=1,IF($B$3=1,50,(_xlfn.RANK.AVG(AG7,$AG$6:$AG$105,1)-1)/($B$3-1)*100),"") | AL7: =IF(AF7=1,IF($B$3=1,50,(_xlfn.RANK.AVG(AH7,$AH$6:$AH$105,1)-1)/($B$3-1)*100),"") | AM7: =IF(AF7=1,IF($B$3=1,50,(_xlfn.RANK.AVG(AI7,$AI$6:$AI$105,1)-1)/($B$3-1)*100),"") | AN7: =IF(AF7=1,IF($B$3=1,50,(_xlfn.RANK.AVG(AJ7,$AJ$6:$AJ$105,1)-1)/($B$3-1)*100),"") | AO7: =IF(AF7=1,ROUND(AVERAGE(AK7:AN7),6),"") | AP7: =IF(AND(AF7=1,C7<>"Y"),R7,"") | AQ7: =IF(AND(ISNUMBER(AP7),Q7="편입 후보"),AP7+(1000-ROW())/1000000,"") | AR7: =IF(A7="","",_xlfn.TEXTJOIN(", ",TRUE,IF(D7="Y","금융·리츠",""),IF(NOT(ISNUMBER(I7)),"영업이익 없음",IF(I7<=0,"영업적자","")),IF(OR(NOT(ISNUMBER(G7)),NOT(ISNUMBER(H7))),"부채비율 자료 없음",IF(G7<=0,"자본잠식",IF(H7/G7>'설정'!$B$8,"부채비율 초과",""))),IF(NOT(ISNUMBER(L7)),"시총 없음",IF(L7<'설정'!$B$9,"시총 미달",""))))
A8: K03 | B8: 예시바이오 | E8: 2026-2Q | F8: -250 | G8: 5000 | H8: 1000 | I8: -200 | J8: 800 | K8: 300 | L8: 20000 | M8: 0 | N8: 3000 | O8: 40000 | P8: 52000 | Q8: =IF(A8="","",IF(C8="Y",IF(AF8=1,IF(AND(R8<'설정'!$B$6,ISNUMBER($H$3)),IF(ROUND($H$3-R8,1)>='설정'!$B$7,"교체 제안 → "&$E$3&" ("&TEXT($H$3,"0.0")&")","보유 유지"),"보유 유지"),"보유 · 점수 없음"),IF(AF8=1,IF(R8>='설정'!$B$5,"편입 후보",""),""))) | R8: =IF(AF8=1,ROUND(IF($B$3=1,50,(_xlfn.RANK.AVG(AO8,$AO$6:$AO$105,1)-1)/($B$3-1)*100),1),"") | S8: =IF(A8="","",IF(AF8=1,_xlfn.TEXTJOIN(". ",TRUE,_xlfn.TEXTJOIN(", ",TRUE,IF(AK8>='설정'!$B$20,"수익성 높음",""),IF(AL8>='설정'!$B$20,"성장 빠름",""),IF(AM8>='설정'!$B$20,"가격 쌈",""),IF(AN8>='설정'!$B$20,"추세 좋음","")),_xlfn.TEXTJOIN(", ",TRUE,IF(AK8<'설정'!$B$21,"수익성 낮음",""),IF(AL8<'설정'!$B$21,"성장 느림",""),IF(AM8<'설정'!$B$21,"가격 비쌈",""),IF(AN8<'설정'!$B$21,"추세 약함","")),IF(_xlfn.TEXTJOIN("·",TRUE,IF(AND(AK8>='설정'!$B$21,AK8<'설정'!$B$20),"수익성",""),IF(AND(AL8>='설정'!$B$21,AL8<'설정'!$B$20),"성장",""),IF(AND(AM8>='설정'!$B$21,AM8<'설정'!$B$20),"가격",""),IF(AND(AN8>='설정'!$B$21,AN8<'설정'!$B$20),"추세",""))="","","보통: "&_xlfn.TEXTJOIN("·",TRUE,IF(AND(AK8>='설정'!$B$21,AK8<'설정'!$B$20),"수익성",""),IF(AND(AL8>='설정'!$B$21,AL8<'설정'!$B$20),"성장",""),IF(AND(AM8>='설정'!$B$21,AM8<'설정'!$B$20),"가격",""),IF(AND(AN8>='설정'!$B$21,AN8<'설정'!$B$20),"추세","")))),IF(X8="통과",AE8,X8))) | T8: =IF(AF8=1,TEXT(Z8,"0.0%")&" · 상위 "&TEXT(($B$3-_xlfn.RANK.AVG(AG8,$AG$6:$AG$105,1)+1)/$B$3*100,"0")&"%",IF(A8="","",IF(Z8="","결측",TEXT(Z8,"0.0%")))) | U8: =IF(AF8=1,TEXT(AA8,"0.0%")&" · 상위 "&TEXT(($B$3-_xlfn.RANK.AVG(AH8,$AH$6:$AH$105,1)+1)/$B$3*100,"0")&"%",IF(A8="","",IF(AA8="","결측",TEXT(AA8,"0.0%")))) | V8: =IF(AF8=1,TEXT(AB8,"0.0%")&" · 상위 "&TEXT(($B$3-_xlfn.RANK.AVG(AI8,$AI$6:$AI$105,1)+1)/$B$3*100,"0")&"%",IF(A8="","",IF(AB8="","결측",TEXT(AB8,"0.0%")))) | W8: =IF(AF8=1,TEXT(AC8,"0.0%")&" · 상위 "&TEXT(($B$3-_xlfn.RANK.AVG(AJ8,$AJ$6:$AJ$105,1)+1)/$B$3*100,"0")&"%",IF(A8="","",IF(AC8="","결측",TEXT(AC8,"0.0%")))) | X8: =IF(A8="","",IF(AR8="","통과","제외: "&AR8)) | Y8: =IF(AND(ISNUMBER(G8),ISNUMBER(H8)),IF(G8>0,H8/G8,""),"") | Z8: =IF(AND(ISNUMBER(F8),ISNUMBER(G8)),IF(G8>0,F8/G8,""),"") | AA8: =IF(AND(ISNUMBER(J8),ISNUMBER(K8)),IF(AND(J8>0,K8>0),(J8/K8)^(1/3)-1,""),"") | AB8: =IF(AND(ISNUMBER(I8),ISNUMBER(L8),ISNUMBER(M8),ISNUMBER(N8)),IF((L8+M8-N8)>0,I8/(L8+M8-N8),""),"") | AC8: =IF(AND(ISNUMBER(O8),ISNUMBER(P8)),IF(AND(O8>0,P8>0),P8/O8-1,""),"") | AD8: =_xlfn.TEXTJOIN(", ",TRUE,IF(Z8="","ROE",""),IF(AA8="","매출성장률",""),IF(AB8="","이익수익률",""),IF(AC8="","12-1 수익률","")) | AE8: =IF(A8="","",IF(AR8<>"","점수 없음(거름망)",IF(AD8="","채점","점수 없음(결측: "&AD8&")"))) | AF8: =IF(AE8="채점",1,"") | AG8: =IF(AF8=1,Z8,"") | AH8: =IF(AF8=1,AA8,"") | AI8: =IF(AF8=1,AB8,"") | AJ8: =IF(AF8=1,AC8,"") | AK8: =IF(AF8=1,IF($B$3=1,50,(_xlfn.RANK.AVG(AG8,$AG$6:$AG$105,1)-1)/($B$3-1)*100),"") | AL8: =IF(AF8=1,IF($B$3=1,50,(_xlfn.RANK.AVG(AH8,$AH$6:$AH$105,1)-1)/($B$3-1)*100),"") | AM8: =IF(AF8=1,IF($B$3=1,50,(_xlfn.RANK.AVG(AI8,$AI$6:$AI$105,1)-1)/($B$3-1)*100),"") | AN8: =IF(AF8=1,IF($B$3=1,50,(_xlfn.RANK.AVG(AJ8,$AJ$6:$AJ$105,1)-1)/($B$3-1)*100),"") | AO8: =IF(AF8=1,ROUND(AVERAGE(AK8:AN8),6),"") | AP8: =IF(AND(AF8=1,C8<>"Y"),R8,"") | AQ8: =IF(AND(ISNUMBER(AP8),Q8="편입 후보"),AP8+(1000-ROW())/1000000,"") | AR8: =IF(A8="","",_xlfn.TEXTJOIN(", ",TRUE,IF(D8="Y","금융·리츠",""),IF(NOT(ISNUMBER(I8)),"영업이익 없음",IF(I8<=0,"영업적자","")),IF(OR(NOT(ISNUMBER(G8)),NOT(ISNUMBER(H8))),"부채비율 자료 없음",IF(G8<=0,"자본잠식",IF(H8/G8>'설정'!$B$8,"부채비율 초과",""))),IF(NOT(ISNUMBER(L8)),"시총 없음",IF(L8<'설정'!$B$9,"시총 미달",""))))
A9: K04 | B9: 예시은행 | D9: Y | E9: 2026-2Q | F9: 3000 | G9: 30000 | H9: 300000 | I9: 4000 | J9: 20000 | K9: 17000 | L9: 25000 | M9: 0 | N9: 0 | O9: 10000 | P9: 11000 | Q9: =IF(A9="","",IF(C9="Y",IF(AF9=1,IF(AND(R9<'설정'!$B$6,ISNUMBER($H$3)),IF(ROUND($H$3-R9,1)>='설정'!$B$7,"교체 제안 → "&$E$3&" ("&TEXT($H$3,"0.0")&")","보유 유지"),"보유 유지"),"보유 · 점수 없음"),IF(AF9=1,IF(R9>='설정'!$B$5,"편입 후보",""),""))) | R9: =IF(AF9=1,ROUND(IF($B$3=1,50,(_xlfn.RANK.AVG(AO9,$AO$6:$AO$105,1)-1)/($B$3-1)*100),1),"") | S9: =IF(A9="","",IF(AF9=1,_xlfn.TEXTJOIN(". ",TRUE,_xlfn.TEXTJOIN(", ",TRUE,IF(AK9>='설정'!$B$20,"수익성 높음",""),IF(AL9>='설정'!$B$20,"성장 빠름",""),IF(AM9>='설정'!$B$20,"가격 쌈",""),IF(AN9>='설정'!$B$20,"추세 좋음","")),_xlfn.TEXTJOIN(", ",TRUE,IF(AK9<'설정'!$B$21,"수익성 낮음",""),IF(AL9<'설정'!$B$21,"성장 느림",""),IF(AM9<'설정'!$B$21,"가격 비쌈",""),IF(AN9<'설정'!$B$21,"추세 약함","")),IF(_xlfn.TEXTJOIN("·",TRUE,IF(AND(AK9>='설정'!$B$21,AK9<'설정'!$B$20),"수익성",""),IF(AND(AL9>='설정'!$B$21,AL9<'설정'!$B$20),"성장",""),IF(AND(AM9>='설정'!$B$21,AM9<'설정'!$B$20),"가격",""),IF(AND(AN9>='설정'!$B$21,AN9<'설정'!$B$20),"추세",""))="","","보통: "&_xlfn.TEXTJOIN("·",TRUE,IF(AND(AK9>='설정'!$B$21,AK9<'설정'!$B$20),"수익성",""),IF(AND(AL9>='설정'!$B$21,AL9<'설정'!$B$20),"성장",""),IF(AND(AM9>='설정'!$B$21,AM9<'설정'!$B$20),"가격",""),IF(AND(AN9>='설정'!$B$21,AN9<'설정'!$B$20),"추세","")))),IF(X9="통과",AE9,X9))) | T9: =IF(AF9=1,TEXT(Z9,"0.0%")&" · 상위 "&TEXT(($B$3-_xlfn.RANK.AVG(AG9,$AG$6:$AG$105,1)+1)/$B$3*100,"0")&"%",IF(A9="","",IF(Z9="","결측",TEXT(Z9,"0.0%")))) | U9: =IF(AF9=1,TEXT(AA9,"0.0%")&" · 상위 "&TEXT(($B$3-_xlfn.RANK.AVG(AH9,$AH$6:$AH$105,1)+1)/$B$3*100,"0")&"%",IF(A9="","",IF(AA9="","결측",TEXT(AA9,"0.0%")))) | V9: =IF(AF9=1,TEXT(AB9,"0.0%")&" · 상위 "&TEXT(($B$3-_xlfn.RANK.AVG(AI9,$AI$6:$AI$105,1)+1)/$B$3*100,"0")&"%",IF(A9="","",IF(AB9="","결측",TEXT(AB9,"0.0%")))) | W9: =IF(AF9=1,TEXT(AC9,"0.0%")&" · 상위 "&TEXT(($B$3-_xlfn.RANK.AVG(AJ9,$AJ$6:$AJ$105,1)+1)/$B$3*100,"0")&"%",IF(A9="","",IF(AC9="","결측",TEXT(AC9,"0.0%")))) | X9: =IF(A9="","",IF(AR9="","통과","제외: "&AR9)) | Y9: =IF(AND(ISNUMBER(G9),ISNUMBER(H9)),IF(G9>0,H9/G9,""),"") | Z9: =IF(AND(ISNUMBER(F9),ISNUMBER(G9)),IF(G9>0,F9/G9,""),"") | AA9: =IF(AND(ISNUMBER(J9),ISNUMBER(K9)),IF(AND(J9>0,K9>0),(J9/K9)^(1/3)-1,""),"") | AB9: =IF(AND(ISNUMBER(I9),ISNUMBER(L9),ISNUMBER(M9),ISNUMBER(N9)),IF((L9+M9-N9)>0,I9/(L9+M9-N9),""),"") | AC9: =IF(AND(ISNUMBER(O9),ISNUMBER(P9)),IF(AND(O9>0,P9>0),P9/O9-1,""),"") | AD9: =_xlfn.TEXTJOIN(", ",TRUE,IF(Z9="","ROE",""),IF(AA9="","매출성장률",""),IF(AB9="","이익수익률",""),IF(AC9="","12-1 수익률","")) | AE9: =IF(A9="","",IF(AR9<>"","점수 없음(거름망)",IF(AD9="","채점","점수 없음(결측: "&AD9&")"))) | AF9: =IF(AE9="채점",1,"") | AG9: =IF(AF9=1,Z9,"") | AH9: =IF(AF9=1,AA9,"") | AI9: =IF(AF9=1,AB9,"") | AJ9: =IF(AF9=1,AC9,"") | AK9: =IF(AF9=1,IF($B$3=1,50,(_xlfn.RANK.AVG(AG9,$AG$6:$AG$105,1)-1)/($B$3-1)*100),"") | AL9: =IF(AF9=1,IF($B$3=1,50,(_xlfn.RANK.AVG(AH9,$AH$6:$AH$105,1)-1)/($B$3-1)*100),"") | AM9: =IF(AF9=1,IF($B$3=1,50,(_xlfn.RANK.AVG(AI9,$AI$6:$AI$105,1)-1)/($B$3-1)*100),"") | AN9: =IF(AF9=1,IF($B$3=1,50,(_xlfn.RANK.AVG(AJ9,$AJ$6:$AJ$105,1)-1)/($B$3-1)*100),"") | AO9: =IF(AF9=1,ROUND(AVERAGE(AK9:AN9),6),"") | AP9: =IF(AND(AF9=1,C9<>"Y"),R9,"") | AQ9: =IF(AND(ISNUMBER(AP9),Q9="편입 후보"),AP9+(1000-ROW())/1000000,"") | AR9: =IF(A9="","",_xlfn.TEXTJOIN(", ",TRUE,IF(D9="Y","금융·리츠",""),IF(NOT(ISNUMBER(I9)),"영업이익 없음",IF(I9<=0,"영업적자","")),IF(OR(NOT(ISNUMBER(G9)),NOT(ISNUMBER(H9))),"부채비율 자료 없음",IF(G9<=0,"자본잠식",IF(H9/G9>'설정'!$B$8,"부채비율 초과",""))),IF(NOT(ISNUMBER(L9)),"시총 없음",IF(L9<'설정'!$B$9,"시총 미달",""))))
A10: K05 | B10: 예시건설 | E10: 2026-2Q | F10: 300 | G10: 5000 | H10: 13000 | I10: 700 | J10: 15000 | K10: 13000 | L10: 6000 | M10: 5000 | N10: 1500 | O10: 20000 | P10: 18000 | Q10: =IF(A10="","",IF(C10="Y",IF(AF10=1,IF(AND(R10<'설정'!$B$6,ISNUMBER($H$3)),IF(ROUND($H$3-R10,1)>='설정'!$B$7,"교체 제안 → "&$E$3&" ("&TEXT($H$3,"0.0")&")","보유 유지"),"보유 유지"),"보유 · 점수 없음"),IF(AF10=1,IF(R10>='설정'!$B$5,"편입 후보",""),""))) | R10: =IF(AF10=1,ROUND(IF($B$3=1,50,(_xlfn.RANK.AVG(AO10,$AO$6:$AO$105,1)-1)/($B$3-1)*100),1),"") | S10: =IF(A10="","",IF(AF10=1,_xlfn.TEXTJOIN(". ",TRUE,_xlfn.TEXTJOIN(", ",TRUE,IF(AK10>='설정'!$B$20,"수익성 높음",""),IF(AL10>='설정'!$B$20,"성장 빠름",""),IF(AM10>='설정'!$B$20,"가격 쌈",""),IF(AN10>='설정'!$B$20,"추세 좋음","")),_xlfn.TEXTJOIN(", ",TRUE,IF(AK10<'설정'!$B$21,"수익성 낮음",""),IF(AL10<'설정'!$B$21,"성장 느림",""),IF(AM10<'설정'!$B$21,"가격 비쌈",""),IF(AN10<'설정'!$B$21,"추세 약함","")),IF(_xlfn.TEXTJOIN("·",TRUE,IF(AND(AK10>='설정'!$B$21,AK10<'설정'!$B$20),"수익성",""),IF(AND(AL10>='설정'!$B$21,AL10<'설정'!$B$20),"성장",""),IF(AND(AM10>='설정'!$B$21,AM10<'설정'!$B$20),"가격",""),IF(AND(AN10>='설정'!$B$21,AN10<'설정'!$B$20),"추세",""))="","","보통: "&_xlfn.TEXTJOIN("·",TRUE,IF(AND(AK10>='설정'!$B$21,AK10<'설정'!$B$20),"수익성",""),IF(AND(AL10>='설정'!$B$21,AL10<'설정'!$B$20),"성장",""),IF(AND(AM10>='설정'!$B$21,AM10<'설정'!$B$20),"가격",""),IF(AND(AN10>='설정'!$B$21,AN10<'설정'!$B$20),"추세","")))),IF(X10="통과",AE10,X10))) | T10: =IF(AF10=1,TEXT(Z10,"0.0%")&" · 상위 "&TEXT(($B$3-_xlfn.RANK.AVG(AG10,$AG$6:$AG$105,1)+1)/$B$3*100,"0")&"%",IF(A10="","",IF(Z10="","결측",TEXT(Z10,"0.0%")))) | U10: =IF(AF10=1,TEXT(AA10,"0.0%")&" · 상위 "&TEXT(($B$3-_xlfn.RANK.AVG(AH10,$AH$6:$AH$105,1)+1)/$B$3*100,"0")&"%",IF(A10="","",IF(AA10="","결측",TEXT(AA10,"0.0%")))) | V10: =IF(AF10=1,TEXT(AB10,"0.0%")&" · 상위 "&TEXT(($B$3-_xlfn.RANK.AVG(AI10,$AI$6:$AI$105,1)+1)/$B$3*100,"0")&"%",IF(A10="","",IF(AB10="","결측",TEXT(AB10,"0.0%")))) | W10: =IF(AF10=1,TEXT(AC10,"0.0%")&" · 상위 "&TEXT(($B$3-_xlfn.RANK.AVG(AJ10,$AJ$6:$AJ$105,1)+1)/$B$3*100,"0")&"%",IF(A10="","",IF(AC10="","결측",TEXT(AC10,"0.0%")))) | X10: =IF(A10="","",IF(AR10="","통과","제외: "&AR10)) | Y10: =IF(AND(ISNUMBER(G10),ISNUMBER(H10)),IF(G10>0,H10/G10,""),"") | Z10: =IF(AND(ISNUMBER(F10),ISNUMBER(G10)),IF(G10>0,F10/G10,""),"") | AA10: =IF(AND(ISNUMBER(J10),ISNUMBER(K10)),IF(AND(J10>0,K10>0),(J10/K10)^(1/3)-1,""),"") | AB10: =IF(AND(ISNUMBER(I10),ISNUMBER(L10),ISNUMBER(M10),ISNUMBER(N10)),IF((L10+M10-N10)>0,I10/(L10+M10-N10),""),"") | AC10: =IF(AND(ISNUMBER(O10),ISNUMBER(P10)),IF(AND(O10>0,P10>0),P10/O10-1,""),"") | AD10: =_xlfn.TEXTJOIN(", ",TRUE,IF(Z10="","ROE",""),IF(AA10="","매출성장률",""),IF(AB10="","이익수익률",""),IF(AC10="","12-1 수익률","")) | AE10: =IF(A10="","",IF(AR10<>"","점수 없음(거름망)",IF(AD10="","채점","점수 없음(결측: "&AD10&")"))) | AF10: =IF(AE10="채점",1,"") | AG10: =IF(AF10=1,Z10,"") | AH10: =IF(AF10=1,AA10,"") | AI10: =IF(AF10=1,AB10,"") | AJ10: =IF(AF10=1,AC10,"") | AK10: =IF(AF10=1,IF($B$3=1,50,(_xlfn.RANK.AVG(AG10,$AG$6:$AG$105,1)-1)/($B$3-1)*100),"") | AL10: =IF(AF10=1,IF($B$3=1,50,(_xlfn.RANK.AVG(AH10,$AH$6:$AH$105,1)-1)/($B$3-1)*100),"") | AM10: =IF(AF10=1,IF($B$3=1,50,(_xlfn.RANK.AVG(AI10,$AI$6:$AI$105,1)-1)/($B$3-1)*100),"") | AN10: =IF(AF10=1,IF($B$3=1,50,(_xlfn.RANK.AVG(AJ10,$AJ$6:$AJ$105,1)-1)/($B$3-1)*100),"") | AO10: =IF(AF10=1,ROUND(AVERAGE(AK10:AN10),6),"") | AP10: =IF(AND(AF10=1,C10<>"Y"),R10,"") | AQ10: =IF(AND(ISNUMBER(AP10),Q10="편입 후보"),AP10+(1000-ROW())/1000000,"") | AR10: =IF(A10="","",_xlfn.TEXTJOIN(", ",TRUE,IF(D10="Y","금융·리츠",""),IF(NOT(ISNUMBER(I10)),"영업이익 없음",IF(I10<=0,"영업적자","")),IF(OR(NOT(ISNUMBER(G10)),NOT(ISNUMBER(H10))),"부채비율 자료 없음",IF(G10<=0,"자본잠식",IF(H10/G10>'설정'!$B$8,"부채비율 초과",""))),IF(NOT(ISNUMBER(L10)),"시총 없음",IF(L10<'설정'!$B$9,"시총 미달",""))))
A11: K06 | B11: 예시식품 | E11: 2026-2Q | F11: 200 | G11: 2000 | H11: 1000 | I11: 280 | J11: 4000 | K11: 3600 | L11: 3000 | M11: 300 | N11: 400 | O11: 15000 | P11: 16000 | Q11: =IF(A11="","",IF(C11="Y",IF(AF11=1,IF(AND(R11<'설정'!$B$6,ISNUMBER($H$3)),IF(ROUND($H$3-R11,1)>='설정'!$B$7,"교체 제안 → "&$E$3&" ("&TEXT($H$3,"0.0")&")","보유 유지"),"보유 유지"),"보유 · 점수 없음"),IF(AF11=1,IF(R11>='설정'!$B$5,"편입 후보",""),""))) | R11: =IF(AF11=1,ROUND(IF($B$3=1,50,(_xlfn.RANK.AVG(AO11,$AO$6:$AO$105,1)-1)/($B$3-1)*100),1),"") | S11: =IF(A11="","",IF(AF11=1,_xlfn.TEXTJOIN(". ",TRUE,_xlfn.TEXTJOIN(", ",TRUE,IF(AK11>='설정'!$B$20,"수익성 높음",""),IF(AL11>='설정'!$B$20,"성장 빠름",""),IF(AM11>='설정'!$B$20,"가격 쌈",""),IF(AN11>='설정'!$B$20,"추세 좋음","")),_xlfn.TEXTJOIN(", ",TRUE,IF(AK11<'설정'!$B$21,"수익성 낮음",""),IF(AL11<'설정'!$B$21,"성장 느림",""),IF(AM11<'설정'!$B$21,"가격 비쌈",""),IF(AN11<'설정'!$B$21,"추세 약함","")),IF(_xlfn.TEXTJOIN("·",TRUE,IF(AND(AK11>='설정'!$B$21,AK11<'설정'!$B$20),"수익성",""),IF(AND(AL11>='설정'!$B$21,AL11<'설정'!$B$20),"성장",""),IF(AND(AM11>='설정'!$B$21,AM11<'설정'!$B$20),"가격",""),IF(AND(AN11>='설정'!$B$21,AN11<'설정'!$B$20),"추세",""))="","","보통: "&_xlfn.TEXTJOIN("·",TRUE,IF(AND(AK11>='설정'!$B$21,AK11<'설정'!$B$20),"수익성",""),IF(AND(AL11>='설정'!$B$21,AL11<'설정'!$B$20),"성장",""),IF(AND(AM11>='설정'!$B$21,AM11<'설정'!$B$20),"가격",""),IF(AND(AN11>='설정'!$B$21,AN11<'설정'!$B$20),"추세","")))),IF(X11="통과",AE11,X11))) | T11: =IF(AF11=1,TEXT(Z11,"0.0%")&" · 상위 "&TEXT(($B$3-_xlfn.RANK.AVG(AG11,$AG$6:$AG$105,1)+1)/$B$3*100,"0")&"%",IF(A11="","",IF(Z11="","결측",TEXT(Z11,"0.0%")))) | U11: =IF(AF11=1,TEXT(AA11,"0.0%")&" · 상위 "&TEXT(($B$3-_xlfn.RANK.AVG(AH11,$AH$6:$AH$105,1)+1)/$B$3*100,"0")&"%",IF(A11="","",IF(AA11="","결측",TEXT(AA11,"0.0%")))) | V11: =IF(AF11=1,TEXT(AB11,"0.0%")&" · 상위 "&TEXT(($B$3-_xlfn.RANK.AVG(AI11,$AI$6:$AI$105,1)+1)/$B$3*100,"0")&"%",IF(A11="","",IF(AB11="","결측",TEXT(AB11,"0.0%")))) | W11: =IF(AF11=1,TEXT(AC11,"0.0%")&" · 상위 "&TEXT(($B$3-_xlfn.RANK.AVG(AJ11,$AJ$6:$AJ$105,1)+1)/$B$3*100,"0")&"%",IF(A11="","",IF(AC11="","결측",TEXT(AC11,"0.0%")))) | X11: =IF(A11="","",IF(AR11="","통과","제외: "&AR11)) | Y11: =IF(AND(ISNUMBER(G11),ISNUMBER(H11)),IF(G11>0,H11/G11,""),"") | Z11: =IF(AND(ISNUMBER(F11),ISNUMBER(G11)),IF(G11>0,F11/G11,""),"") | AA11: =IF(AND(ISNUMBER(J11),ISNUMBER(K11)),IF(AND(J11>0,K11>0),(J11/K11)^(1/3)-1,""),"") | AB11: =IF(AND(ISNUMBER(I11),ISNUMBER(L11),ISNUMBER(M11),ISNUMBER(N11)),IF((L11+M11-N11)>0,I11/(L11+M11-N11),""),"") | AC11: =IF(AND(ISNUMBER(O11),ISNUMBER(P11)),IF(AND(O11>0,P11>0),P11/O11-1,""),"") | AD11: =_xlfn.TEXTJOIN(", ",TRUE,IF(Z11="","ROE",""),IF(AA11="","매출성장률",""),IF(AB11="","이익수익률",""),IF(AC11="","12-1 수익률","")) | AE11: =IF(A11="","",IF(AR11<>"","점수 없음(거름망)",IF(AD11="","채점","점수 없음(결측: "&AD11&")"))) | AF11: =IF(AE11="채점",1,"") | AG11: =IF(AF11=1,Z11,"") | AH11: =IF(AF11=1,AA11,"") | AI11: =IF(AF11=1,AB11,"") | AJ11: =IF(AF11=1,AC11,"") | AK11: =IF(AF11=1,IF($B$3=1,50,(_xlfn.RANK.AVG(AG11,$AG$6:$AG$105,1)-1)/($B$3-1)*100),"") | AL11: =IF(AF11=1,IF($B$3=1,50,(_xlfn.RANK.AVG(AH11,$AH$6:$AH$105,1)-1)/($B$3-1)*100),"") | AM11: =IF(AF11=1,IF($B$3=1,50,(_xlfn.RANK.AVG(AI11,$AI$6:$AI$105,1)-1)/($B$3-1)*100),"") | AN11: =IF(AF11=1,IF($B$3=1,50,(_xlfn.RANK.AVG(AJ11,$AJ$6:$AJ$105,1)-1)/($B$3-1)*100),"") | AO11: =IF(AF11=1,ROUND(AVERAGE(AK11:AN11),6),"") | AP11: =IF(AND(AF11=1,C11<>"Y"),R11,"") | AQ11: =IF(AND(ISNUMBER(AP11),Q11="편입 후보"),AP11+(1000-ROW())/1000000,"") | AR11: =IF(A11="","",_xlfn.TEXTJOIN(", ",TRUE,IF(D11="Y","금융·리츠",""),IF(NOT(ISNUMBER(I11)),"영업이익 없음",IF(I11<=0,"영업적자","")),IF(OR(NOT(ISNUMBER(G11)),NOT(ISNUMBER(H11))),"부채비율 자료 없음",IF(G11<=0,"자본잠식",IF(H11/G11>'설정'!$B$8,"부채비율 초과",""))),IF(NOT(ISNUMBER(L11)),"시총 없음",IF(L11<'설정'!$B$9,"시총 미달",""))))
A12: K07 | B12: 예시소프트 | E12: 2026-2Q | F12: 900 | G12: 3000 | H12: 1200 | I12: 1100 | J12: 5000 | K12: 2500 | L12: 12000 | M12: 0 | N12: 1500 | O12: 20000 | P12: 31000 | Q12: =IF(A12="","",IF(C12="Y",IF(AF12=1,IF(AND(R12<'설정'!$B$6,ISNUMBER($H$3)),IF(ROUND($H$3-R12,1)>='설정'!$B$7,"교체 제안 → "&$E$3&" ("&TEXT($H$3,"0.0")&")","보유 유지"),"보유 유지"),"보유 · 점수 없음"),IF(AF12=1,IF(R12>='설정'!$B$5,"편입 후보",""),""))) | R12: =IF(AF12=1,ROUND(IF($B$3=1,50,(_xlfn.RANK.AVG(AO12,$AO$6:$AO$105,1)-1)/($B$3-1)*100),1),"") | S12: =IF(A12="","",IF(AF12=1,_xlfn.TEXTJOIN(". ",TRUE,_xlfn.TEXTJOIN(", ",TRUE,IF(AK12>='설정'!$B$20,"수익성 높음",""),IF(AL12>='설정'!$B$20,"성장 빠름",""),IF(AM12>='설정'!$B$20,"가격 쌈",""),IF(AN12>='설정'!$B$20,"추세 좋음","")),_xlfn.TEXTJOIN(", ",TRUE,IF(AK12<'설정'!$B$21,"수익성 낮음",""),IF(AL12<'설정'!$B$21,"성장 느림",""),IF(AM12<'설정'!$B$21,"가격 비쌈",""),IF(AN12<'설정'!$B$21,"추세 약함","")),IF(_xlfn.TEXTJOIN("·",TRUE,IF(AND(AK12>='설정'!$B$21,AK12<'설정'!$B$20),"수익성",""),IF(AND(AL12>='설정'!$B$21,AL12<'설정'!$B$20),"성장",""),IF(AND(AM12>='설정'!$B$21,AM12<'설정'!$B$20),"가격",""),IF(AND(AN12>='설정'!$B$21,AN12<'설정'!$B$20),"추세",""))="","","보통: "&_xlfn.TEXTJOIN("·",TRUE,IF(AND(AK12>='설정'!$B$21,AK12<'설정'!$B$20),"수익성",""),IF(AND(AL12>='설정'!$B$21,AL12<'설정'!$B$20),"성장",""),IF(AND(AM12>='설정'!$B$21,AM12<'설정'!$B$20),"가격",""),IF(AND(AN12>='설정'!$B$21,AN12<'설정'!$B$20),"추세","")))),IF(X12="통과",AE12,X12))) | T12: =IF(AF12=1,TEXT(Z12,"0.0%")&" · 상위 "&TEXT(($B$3-_xlfn.RANK.AVG(AG12,$AG$6:$AG$105,1)+1)/$B$3*100,"0")&"%",IF(A12="","",IF(Z12="","결측",TEXT(Z12,"0.0%")))) | U12: =IF(AF12=1,TEXT(AA12,"0.0%")&" · 상위 "&TEXT(($B$3-_xlfn.RANK.AVG(AH12,$AH$6:$AH$105,1)+1)/$B$3*100,"0")&"%",IF(A12="","",IF(AA12="","결측",TEXT(AA12,"0.0%")))) | V12: =IF(AF12=1,TEXT(AB12,"0.0%")&" · 상위 "&TEXT(($B$3-_xlfn.RANK.AVG(AI12,$AI$6:$AI$105,1)+1)/$B$3*100,"0")&"%",IF(A12="","",IF(AB12="","결측",TEXT(AB12,"0.0%")))) | W12: =IF(AF12=1,TEXT(AC12,"0.0%")&" · 상위 "&TEXT(($B$3-_xlfn.RANK.AVG(AJ12,$AJ$6:$AJ$105,1)+1)/$B$3*100,"0")&"%",IF(A12="","",IF(AC12="","결측",TEXT(AC12,"0.0%")))) | X12: =IF(A12="","",IF(AR12="","통과","제외: "&AR12)) | Y12: =IF(AND(ISNUMBER(G12),ISNUMBER(H12)),IF(G12>0,H12/G12,""),"") | Z12: =IF(AND(ISNUMBER(F12),ISNUMBER(G12)),IF(G12>0,F12/G12,""),"") | AA12: =IF(AND(ISNUMBER(J12),ISNUMBER(K12)),IF(AND(J12>0,K12>0),(J12/K12)^(1/3)-1,""),"") | AB12: =IF(AND(ISNUMBER(I12),ISNUMBER(L12),ISNUMBER(M12),ISNUMBER(N12)),IF((L12+M12-N12)>0,I12/(L12+M12-N12),""),"") | AC12: =IF(AND(ISNUMBER(O12),ISNUMBER(P12)),IF(AND(O12>0,P12>0),P12/O12-1,""),"") | AD12: =_xlfn.TEXTJOIN(", ",TRUE,IF(Z12="","ROE",""),IF(AA12="","매출성장률",""),IF(AB12="","이익수익률",""),IF(AC12="","12-1 수익률","")) | AE12: =IF(A12="","",IF(AR12<>"","점수 없음(거름망)",IF(AD12="","채점","점수 없음(결측: "&AD12&")"))) | AF12: =IF(AE12="채점",1,"") | AG12: =IF(AF12=1,Z12,"") | AH12: =IF(AF12=1,AA12,"") | AI12: =IF(AF12=1,AB12,"") | AJ12: =IF(AF12=1,AC12,"") | AK12: =IF(AF12=1,IF($B$3=1,50,(_xlfn.RANK.AVG(AG12,$AG$6:$AG$105,1)-1)/($B$3-1)*100),"") | AL12: =IF(AF12=1,IF($B$3=1,50,(_xlfn.RANK.AVG(AH12,$AH$6:$AH$105,1)-1)/($B$3-1)*100),"") | AM12: =IF(AF12=1,IF($B$3=1,50,(_xlfn.RANK.AVG(AI12,$AI$6:$AI$105,1)-1)/($B$3-1)*100),"") | AN12: =IF(AF12=1,IF($B$3=1,50,(_xlfn.RANK.AVG(AJ12,$AJ$6:$AJ$105,1)-1)/($B$3-1)*100),"") | AO12: =IF(AF12=1,ROUND(AVERAGE(AK12:AN12),6),"") | AP12: =IF(AND(AF12=1,C12<>"Y"),R12,"") | AQ12: =IF(AND(ISNUMBER(AP12),Q12="편입 후보"),AP12+(1000-ROW())/1000000,"") | AR12: =IF(A12="","",_xlfn.TEXTJOIN(", ",TRUE,IF(D12="Y","금융·리츠",""),IF(NOT(ISNUMBER(I12)),"영업이익 없음",IF(I12<=0,"영업적자","")),IF(OR(NOT(ISNUMBER(G12)),NOT(ISNUMBER(H12))),"부채비율 자료 없음",IF(G12<=0,"자본잠식",IF(H12/G12>'설정'!$B$8,"부채비율 초과",""))),IF(NOT(ISNUMBER(L12)),"시총 없음",IF(L12<'설정'!$B$9,"시총 미달",""))))
A13: K08 | B13: 예시기계 | E13: 2026-2Q | F13: 500 | G13: 6000 | H13: 5000 | I13: 750 | J13: 9000 | K13: 8000 | L13: 7000 | M13: 2000 | N13: 800 | O13: 25000 | P13: 26500 | Q13: =IF(A13="","",IF(C13="Y",IF(AF13=1,IF(AND(R13<'설정'!$B$6,ISNUMBER($H$3)),IF(ROUND($H$3-R13,1)>='설정'!$B$7,"교체 제안 → "&$E$3&" ("&TEXT($H$3,"0.0")&")","보유 유지"),"보유 유지"),"보유 · 점수 없음"),IF(AF13=1,IF(R13>='설정'!$B$5,"편입 후보",""),""))) | R13: =IF(AF13=1,ROUND(IF($B$3=1,50,(_xlfn.RANK.AVG(AO13,$AO$6:$AO$105,1)-1)/($B$3-1)*100),1),"") | S13: =IF(A13="","",IF(AF13=1,_xlfn.TEXTJOIN(". ",TRUE,_xlfn.TEXTJOIN(", ",TRUE,IF(AK13>='설정'!$B$20,"수익성 높음",""),IF(AL13>='설정'!$B$20,"성장 빠름",""),IF(AM13>='설정'!$B$20,"가격 쌈",""),IF(AN13>='설정'!$B$20,"추세 좋음","")),_xlfn.TEXTJOIN(", ",TRUE,IF(AK13<'설정'!$B$21,"수익성 낮음",""),IF(AL13<'설정'!$B$21,"성장 느림",""),IF(AM13<'설정'!$B$21,"가격 비쌈",""),IF(AN13<'설정'!$B$21,"추세 약함","")),IF(_xlfn.TEXTJOIN("·",TRUE,IF(AND(AK13>='설정'!$B$21,AK13<'설정'!$B$20),"수익성",""),IF(AND(AL13>='설정'!$B$21,AL13<'설정'!$B$20),"성장",""),IF(AND(AM13>='설정'!$B$21,AM13<'설정'!$B$20),"가격",""),IF(AND(AN13>='설정'!$B$21,AN13<'설정'!$B$20),"추세",""))="","","보통: "&_xlfn.TEXTJOIN("·",TRUE,IF(AND(AK13>='설정'!$B$21,AK13<'설정'!$B$20),"수익성",""),IF(AND(AL13>='설정'!$B$21,AL13<'설정'!$B$20),"성장",""),IF(AND(AM13>='설정'!$B$21,AM13<'설정'!$B$20),"가격",""),IF(AND(AN13>='설정'!$B$21,AN13<'설정'!$B$20),"추세","")))),IF(X13="통과",AE13,X13))) | T13: =IF(AF13=1,TEXT(Z13,"0.0%")&" · 상위 "&TEXT(($B$3-_xlfn.RANK.AVG(AG13,$AG$6:$AG$105,1)+1)/$B$3*100,"0")&"%",IF(A13="","",IF(Z13="","결측",TEXT(Z13,"0.0%")))) | U13: =IF(AF13=1,TEXT(AA13,"0.0%")&" · 상위 "&TEXT(($B$3-_xlfn.RANK.AVG(AH13,$AH$6:$AH$105,1)+1)/$B$3*100,"0")&"%",IF(A13="","",IF(AA13="","결측",TEXT(AA13,"0.0%")))) | V13: =IF(AF13=1,TEXT(AB13,"0.0%")&" · 상위 "&TEXT(($B$3-_xlfn.RANK.AVG(AI13,$AI$6:$AI$105,1)+1)/$B$3*100,"0")&"%",IF(A13="","",IF(AB13="","결측",TEXT(AB13,"0.0%")))) | W13: =IF(AF13=1,TEXT(AC13,"0.0%")&" · 상위 "&TEXT(($B$3-_xlfn.RANK.AVG(AJ13,$AJ$6:$AJ$105,1)+1)/$B$3*100,"0")&"%",IF(A13="","",IF(AC13="","결측",TEXT(AC13,"0.0%")))) | X13: =IF(A13="","",IF(AR13="","통과","제외: "&AR13)) | Y13: =IF(AND(ISNUMBER(G13),ISNUMBER(H13)),IF(G13>0,H13/G13,""),"") | Z13: =IF(AND(ISNUMBER(F13),ISNUMBER(G13)),IF(G13>0,F13/G13,""),"") | AA13: =IF(AND(ISNUMBER(J13),ISNUMBER(K13)),IF(AND(J13>0,K13>0),(J13/K13)^(1/3)-1,""),"") | AB13: =IF(AND(ISNUMBER(I13),ISNUMBER(L13),ISNUMBER(M13),ISNUMBER(N13)),IF((L13+M13-N13)>0,I13/(L13+M13-N13),""),"") | AC13: =IF(AND(ISNUMBER(O13),ISNUMBER(P13)),IF(AND(O13>0,P13>0),P13/O13-1,""),"") | AD13: =_xlfn.TEXTJOIN(", ",TRUE,IF(Z13="","ROE",""),IF(AA13="","매출성장률",""),IF(AB13="","이익수익률",""),IF(AC13="","12-1 수익률","")) | AE13: =IF(A13="","",IF(AR13<>"","점수 없음(거름망)",IF(AD13="","채점","점수 없음(결측: "&AD13&")"))) | AF13: =IF(AE13="채점",1,"") | AG13: =IF(AF13=1,Z13,"") | AH13: =IF(AF13=1,AA13,"") | AI13: =IF(AF13=1,AB13,"") | AJ13: =IF(AF13=1,AC13,"") | AK13: =IF(AF13=1,IF($B$3=1,50,(_xlfn.RANK.AVG(AG13,$AG$6:$AG$105,1)-1)/($B$3-1)*100),"") | AL13: =IF(AF13=1,IF($B$3=1,50,(_xlfn.RANK.AVG(AH13,$AH$6:$AH$105,1)-1)/($B$3-1)*100),"") | AM13: =IF(AF13=1,IF($B$3=1,50,(_xlfn.RANK.AVG(AI13,$AI$6:$AI$105,1)-1)/($B$3-1)*100),"") | AN13: =IF(AF13=1,IF($B$3=1,50,(_xlfn.RANK.AVG(AJ13,$AJ$6:$AJ$105,1)-1)/($B$3-1)*100),"") | AO13: =IF(AF13=1,ROUND(AVERAGE(AK13:AN13),6),"") | AP13: =IF(AND(AF13=1,C13<>"Y"),R13,"") | AQ13: =IF(AND(ISNUMBER(AP13),Q13="편입 후보"),AP13+(1000-ROW())/1000000,"") | AR13: =IF(A13="","",_xlfn.TEXTJOIN(", ",TRUE,IF(D13="Y","금융·리츠",""),IF(NOT(ISNUMBER(I13)),"영업이익 없음",IF(I13<=0,"영업적자","")),IF(OR(NOT(ISNUMBER(G13)),NOT(ISNUMBER(H13))),"부채비율 자료 없음",IF(G13<=0,"자본잠식",IF(H13/G13>'설정'!$B$8,"부채비율 초과",""))),IF(NOT(ISNUMBER(L13)),"시총 없음",IF(L13<'설정'!$B$9,"시총 미달",""))))
A14: K09 | B14: 예시에너지 | E14: 2026-2Q | F14: 700 | G14: 7000 | H14: 6000 | I14: 1000 | J14: 10000 | K14: 6000 | L14: 9000 | M14: 3000 | N14: 1000 | P14: 33000 | Q14: =IF(A14="","",IF(C14="Y",IF(AF14=1,IF(AND(R14<'설정'!$B$6,ISNUMBER($H$3)),IF(ROUND($H$3-R14,1)>='설정'!$B$7,"교체 제안 → "&$E$3&" ("&TEXT($H$3,"0.0")&")","보유 유지"),"보유 유지"),"보유 · 점수 없음"),IF(AF14=1,IF(R14>='설정'!$B$5,"편입 후보",""),""))) | R14: =IF(AF14=1,ROUND(IF($B$3=1,50,(_xlfn.RANK.AVG(AO14,$AO$6:$AO$105,1)-1)/($B$3-1)*100),1),"") | S14: =IF(A14="","",IF(AF14=1,_xlfn.TEXTJOIN(". ",TRUE,_xlfn.TEXTJOIN(", ",TRUE,IF(AK14>='설정'!$B$20,"수익성 높음",""),IF(AL14>='설정'!$B$20,"성장 빠름",""),IF(AM14>='설정'!$B$20,"가격 쌈",""),IF(AN14>='설정'!$B$20,"추세 좋음","")),_xlfn.TEXTJOIN(", ",TRUE,IF(AK14<'설정'!$B$21,"수익성 낮음",""),IF(AL14<'설정'!$B$21,"성장 느림",""),IF(AM14<'설정'!$B$21,"가격 비쌈",""),IF(AN14<'설정'!$B$21,"추세 약함","")),IF(_xlfn.TEXTJOIN("·",TRUE,IF(AND(AK14>='설정'!$B$21,AK14<'설정'!$B$20),"수익성",""),IF(AND(AL14>='설정'!$B$21,AL14<'설정'!$B$20),"성장",""),IF(AND(AM14>='설정'!$B$21,AM14<'설정'!$B$20),"가격",""),IF(AND(AN14>='설정'!$B$21,AN14<'설정'!$B$20),"추세",""))="","","보통: "&_xlfn.TEXTJOIN("·",TRUE,IF(AND(AK14>='설정'!$B$21,AK14<'설정'!$B$20),"수익성",""),IF(AND(AL14>='설정'!$B$21,AL14<'설정'!$B$20),"성장",""),IF(AND(AM14>='설정'!$B$21,AM14<'설정'!$B$20),"가격",""),IF(AND(AN14>='설정'!$B$21,AN14<'설정'!$B$20),"추세","")))),IF(X14="통과",AE14,X14))) | T14: =IF(AF14=1,TEXT(Z14,"0.0%")&" · 상위 "&TEXT(($B$3-_xlfn.RANK.AVG(AG14,$AG$6:$AG$105,1)+1)/$B$3*100,"0")&"%",IF(A14="","",IF(Z14="","결측",TEXT(Z14,"0.0%")))) | U14: =IF(AF14=1,TEXT(AA14,"0.0%")&" · 상위 "&TEXT(($B$3-_xlfn.RANK.AVG(AH14,$AH$6:$AH$105,1)+1)/$B$3*100,"0")&"%",IF(A14="","",IF(AA14="","결측",TEXT(AA14,"0.0%")))) | V14: =IF(AF14=1,TEXT(AB14,"0.0%")&" · 상위 "&TEXT(($B$3-_xlfn.RANK.AVG(AI14,$AI$6:$AI$105,1)+1)/$B$3*100,"0")&"%",IF(A14="","",IF(AB14="","결측",TEXT(AB14,"0.0%")))) | W14: =IF(AF14=1,TEXT(AC14,"0.0%")&" · 상위 "&TEXT(($B$3-_xlfn.RANK.AVG(AJ14,$AJ$6:$AJ$105,1)+1)/$B$3*100,"0")&"%",IF(A14="","",IF(AC14="","결측",TEXT(AC14,"0.0%")))) | X14: =IF(A14="","",IF(AR14="","통과","제외: "&AR14)) | Y14: =IF(AND(ISNUMBER(G14),ISNUMBER(H14)),IF(G14>0,H14/G14,""),"") | Z14: =IF(AND(ISNUMBER(F14),ISNUMBER(G14)),IF(G14>0,F14/G14,""),"") | AA14: =IF(AND(ISNUMBER(J14),ISNUMBER(K14)),IF(AND(J14>0,K14>0),(J14/K14)^(1/3)-1,""),"") | AB14: =IF(AND(ISNUMBER(I14),ISNUMBER(L14),ISNUMBER(M14),ISNUMBER(N14)),IF((L14+M14-N14)>0,I14/(L14+M14-N14),""),"") | AC14: =IF(AND(ISNUMBER(O14),ISNUMBER(P14)),IF(AND(O14>0,P14>0),P14/O14-1,""),"") | AD14: =_xlfn.TEXTJOIN(", ",TRUE,IF(Z14="","ROE",""),IF(AA14="","매출성장률",""),IF(AB14="","이익수익률",""),IF(AC14="","12-1 수익률","")) | AE14: =IF(A14="","",IF(AR14<>"","점수 없음(거름망)",IF(AD14="","채점","점수 없음(결측: "&AD14&")"))) | AF14: =IF(AE14="채점",1,"") | AG14: =IF(AF14=1,Z14,"") | AH14: =IF(AF14=1,AA14,"") | AI14: =IF(AF14=1,AB14,"") | AJ14: =IF(AF14=1,AC14,"") | AK14: =IF(AF14=1,IF($B$3=1,50,(_xlfn.RANK.AVG(AG14,$AG$6:$AG$105,1)-1)/($B$3-1)*100),"") | AL14: =IF(AF14=1,IF($B$3=1,50,(_xlfn.RANK.AVG(AH14,$AH$6:$AH$105,1)-1)/($B$3-1)*100),"") | AM14: =IF(AF14=1,IF($B$3=1,50,(_xlfn.RANK.AVG(AI14,$AI$6:$AI$105,1)-1)/($B$3-1)*100),"") | AN14: =IF(AF14=1,IF($B$3=1,50,(_xlfn.RANK.AVG(AJ14,$AJ$6:$AJ$105,1)-1)/($B$3-1)*100),"") | AO14: =IF(AF14=1,ROUND(AVERAGE(AK14:AN14),6),"") | AP14: =IF(AND(AF14=1,C14<>"Y"),R14,"") | AQ14: =IF(AND(ISNUMBER(AP14),Q14="편입 후보"),AP14+(1000-ROW())/1000000,"") | AR14: =IF(A14="","",_xlfn.TEXTJOIN(", ",TRUE,IF(D14="Y","금융·리츠",""),IF(NOT(ISNUMBER(I14)),"영업이익 없음",IF(I14<=0,"영업적자","")),IF(OR(NOT(ISNUMBER(G14)),NOT(ISNUMBER(H14))),"부채비율 자료 없음",IF(G14<=0,"자본잠식",IF(H14/G14>'설정'!$B$8,"부채비율 초과",""))),IF(NOT(ISNUMBER(L14)),"시총 없음",IF(L14<'설정'!$B$9,"시총 미달",""))))
A15: K10 | B15: 예시소재 | E15: 2026-2Q | F15: 650 | G15: 4500 | H15: 3000 | I15: 900 | J15: 6500 | K15: 5000 | L15: 8000 | M15: 1200 | N15: 900 | O15: 18000 | P15: 21000 | Q15: =IF(A15="","",IF(C15="Y",IF(AF15=1,IF(AND(R15<'설정'!$B$6,ISNUMBER($H$3)),IF(ROUND($H$3-R15,1)>='설정'!$B$7,"교체 제안 → "&$E$3&" ("&TEXT($H$3,"0.0")&")","보유 유지"),"보유 유지"),"보유 · 점수 없음"),IF(AF15=1,IF(R15>='설정'!$B$5,"편입 후보",""),""))) | R15: =IF(AF15=1,ROUND(IF($B$3=1,50,(_xlfn.RANK.AVG(AO15,$AO$6:$AO$105,1)-1)/($B$3-1)*100),1),"") | S15: =IF(A15="","",IF(AF15=1,_xlfn.TEXTJOIN(". ",TRUE,_xlfn.TEXTJOIN(", ",TRUE,IF(AK15>='설정'!$B$20,"수익성 높음",""),IF(AL15>='설정'!$B$20,"성장 빠름",""),IF(AM15>='설정'!$B$20,"가격 쌈",""),IF(AN15>='설정'!$B$20,"추세 좋음","")),_xlfn.TEXTJOIN(", ",TRUE,IF(AK15<'설정'!$B$21,"수익성 낮음",""),IF(AL15<'설정'!$B$21,"성장 느림",""),IF(AM15<'설정'!$B$21,"가격 비쌈",""),IF(AN15<'설정'!$B$21,"추세 약함","")),IF(_xlfn.TEXTJOIN("·",TRUE,IF(AND(AK15>='설정'!$B$21,AK15<'설정'!$B$20),"수익성",""),IF(AND(AL15>='설정'!$B$21,AL15<'설정'!$B$20),"성장",""),IF(AND(AM15>='설정'!$B$21,AM15<'설정'!$B$20),"가격",""),IF(AND(AN15>='설정'!$B$21,AN15<'설정'!$B$20),"추세",""))="","","보통: "&_xlfn.TEXTJOIN("·",TRUE,IF(AND(AK15>='설정'!$B$21,AK15<'설정'!$B$20),"수익성",""),IF(AND(AL15>='설정'!$B$21,AL15<'설정'!$B$20),"성장",""),IF(AND(AM15>='설정'!$B$21,AM15<'설정'!$B$20),"가격",""),IF(AND(AN15>='설정'!$B$21,AN15<'설정'!$B$20),"추세","")))),IF(X15="통과",AE15,X15))) | T15: =IF(AF15=1,TEXT(Z15,"0.0%")&" · 상위 "&TEXT(($B$3-_xlfn.RANK.AVG(AG15,$AG$6:$AG$105,1)+1)/$B$3*100,"0")&"%",IF(A15="","",IF(Z15="","결측",TEXT(Z15,"0.0%")))) | U15: =IF(AF15=1,TEXT(AA15,"0.0%")&" · 상위 "&TEXT(($B$3-_xlfn.RANK.AVG(AH15,$AH$6:$AH$105,1)+1)/$B$3*100,"0")&"%",IF(A15="","",IF(AA15="","결측",TEXT(AA15,"0.0%")))) | V15: =IF(AF15=1,TEXT(AB15,"0.0%")&" · 상위 "&TEXT(($B$3-_xlfn.RANK.AVG(AI15,$AI$6:$AI$105,1)+1)/$B$3*100,"0")&"%",IF(A15="","",IF(AB15="","결측",TEXT(AB15,"0.0%")))) | W15: =IF(AF15=1,TEXT(AC15,"0.0%")&" · 상위 "&TEXT(($B$3-_xlfn.RANK.AVG(AJ15,$AJ$6:$AJ$105,1)+1)/$B$3*100,"0")&"%",IF(A15="","",IF(AC15="","결측",TEXT(AC15,"0.0%")))) | X15: =IF(A15="","",IF(AR15="","통과","제외: "&AR15)) | Y15: =IF(AND(ISNUMBER(G15),ISNUMBER(H15)),IF(G15>0,H15/G15,""),"") | Z15: =IF(AND(ISNUMBER(F15),ISNUMBER(G15)),IF(G15>0,F15/G15,""),"") | AA15: =IF(AND(ISNUMBER(J15),ISNUMBER(K15)),IF(AND(J15>0,K15>0),(J15/K15)^(1/3)-1,""),"") | AB15: =IF(AND(ISNUMBER(I15),ISNUMBER(L15),ISNUMBER(M15),ISNUMBER(N15)),IF((L15+M15-N15)>0,I15/(L15+M15-N15),""),"") | AC15: =IF(AND(ISNUMBER(O15),ISNUMBER(P15)),IF(AND(O15>0,P15>0),P15/O15-1,""),"") | AD15: =_xlfn.TEXTJOIN(", ",TRUE,IF(Z15="","ROE",""),IF(AA15="","매출성장률",""),IF(AB15="","이익수익률",""),IF(AC15="","12-1 수익률","")) | AE15: =IF(A15="","",IF(AR15<>"","점수 없음(거름망)",IF(AD15="","채점","점수 없음(결측: "&AD15&")"))) | AF15: =IF(AE15="채점",1,"") | AG15: =IF(AF15=1,Z15,"") | AH15: =IF(AF15=1,AA15,"") | AI15: =IF(AF15=1,AB15,"") | AJ15: =IF(AF15=1,AC15,"") | AK15: =IF(AF15=1,IF($B$3=1,50,(_xlfn.RANK.AVG(AG15,$AG$6:$AG$105,1)-1)/($B$3-1)*100),"") | AL15: =IF(AF15=1,IF($B$3=1,50,(_xlfn.RANK.AVG(AH15,$AH$6:$AH$105,1)-1)/($B$3-1)*100),"") | AM15: =IF(AF15=1,IF($B$3=1,50,(_xlfn.RANK.AVG(AI15,$AI$6:$AI$105,1)-1)/($B$3-1)*100),"") | AN15: =IF(AF15=1,IF($B$3=1,50,(_xlfn.RANK.AVG(AJ15,$AJ$6:$AJ$105,1)-1)/($B$3-1)*100),"") | AO15: =IF(AF15=1,ROUND(AVERAGE(AK15:AN15),6),"") | AP15: =IF(AND(AF15=1,C15<>"Y"),R15,"") | AQ15: =IF(AND(ISNUMBER(AP15),Q15="편입 후보"),AP15+(1000-ROW())/1000000,"") | AR15: =IF(A15="","",_xlfn.TEXTJOIN(", ",TRUE,IF(D15="Y","금융·리츠",""),IF(NOT(ISNUMBER(I15)),"영업이익 없음",IF(I15<=0,"영업적자","")),IF(OR(NOT(ISNUMBER(G15)),NOT(ISNUMBER(H15))),"부채비율 자료 없음",IF(G15<=0,"자본잠식",IF(H15/G15>'설정'!$B$8,"부채비율 초과",""))),IF(NOT(ISNUMBER(L15)),"시총 없음",IF(L15<'설정'!$B$9,"시총 미달",""))))
A16: K11 | B16: 예시로봇 | E16: 2026-2Q | F16: 300 | G16: 2500 | H16: 1500 | I16: 400 | J16: 3000 | K16: 1200 | L16: 18000 | M16: 500 | N16: 1200 | O16: 30000 | P16: 45000 | Q16: =IF(A16="","",IF(C16="Y",IF(AF16=1,IF(AND(R16<'설정'!$B$6,ISNUMBER($H$3)),IF(ROUND($H$3-R16,1)>='설정'!$B$7,"교체 제안 → "&$E$3&" ("&TEXT($H$3,"0.0")&")","보유 유지"),"보유 유지"),"보유 · 점수 없음"),IF(AF16=1,IF(R16>='설정'!$B$5,"편입 후보",""),""))) | R16: =IF(AF16=1,ROUND(IF($B$3=1,50,(_xlfn.RANK.AVG(AO16,$AO$6:$AO$105,1)-1)/($B$3-1)*100),1),"") | S16: =IF(A16="","",IF(AF16=1,_xlfn.TEXTJOIN(". ",TRUE,_xlfn.TEXTJOIN(", ",TRUE,IF(AK16>='설정'!$B$20,"수익성 높음",""),IF(AL16>='설정'!$B$20,"성장 빠름",""),IF(AM16>='설정'!$B$20,"가격 쌈",""),IF(AN16>='설정'!$B$20,"추세 좋음","")),_xlfn.TEXTJOIN(", ",TRUE,IF(AK16<'설정'!$B$21,"수익성 낮음",""),IF(AL16<'설정'!$B$21,"성장 느림",""),IF(AM16<'설정'!$B$21,"가격 비쌈",""),IF(AN16<'설정'!$B$21,"추세 약함","")),IF(_xlfn.TEXTJOIN("·",TRUE,IF(AND(AK16>='설정'!$B$21,AK16<'설정'!$B$20),"수익성",""),IF(AND(AL16>='설정'!$B$21,AL16<'설정'!$B$20),"성장",""),IF(AND(AM16>='설정'!$B$21,AM16<'설정'!$B$20),"가격",""),IF(AND(AN16>='설정'!$B$21,AN16<'설정'!$B$20),"추세",""))="","","보통: "&_xlfn.TEXTJOIN("·",TRUE,IF(AND(AK16>='설정'!$B$21,AK16<'설정'!$B$20),"수익성",""),IF(AND(AL16>='설정'!$B$21,AL16<'설정'!$B$20),"성장",""),IF(AND(AM16>='설정'!$B$21,AM16<'설정'!$B$20),"가격",""),IF(AND(AN16>='설정'!$B$21,AN16<'설정'!$B$20),"추세","")))),IF(X16="통과",AE16,X16))) | T16: =IF(AF16=1,TEXT(Z16,"0.0%")&" · 상위 "&TEXT(($B$3-_xlfn.RANK.AVG(AG16,$AG$6:$AG$105,1)+1)/$B$3*100,"0")&"%",IF(A16="","",IF(Z16="","결측",TEXT(Z16,"0.0%")))) | U16: =IF(AF16=1,TEXT(AA16,"0.0%")&" · 상위 "&TEXT(($B$3-_xlfn.RANK.AVG(AH16,$AH$6:$AH$105,1)+1)/$B$3*100,"0")&"%",IF(A16="","",IF(AA16="","결측",TEXT(AA16,"0.0%")))) | V16: =IF(AF16=1,TEXT(AB16,"0.0%")&" · 상위 "&TEXT(($B$3-_xlfn.RANK.AVG(AI16,$AI$6:$AI$105,1)+1)/$B$3*100,"0")&"%",IF(A16="","",IF(AB16="","결측",TEXT(AB16,"0.0%")))) | W16: =IF(AF16=1,TEXT(AC16,"0.0%")&" · 상위 "&TEXT(($B$3-_xlfn.RANK.AVG(AJ16,$AJ$6:$AJ$105,1)+1)/$B$3*100,"0")&"%",IF(A16="","",IF(AC16="","결측",TEXT(AC16,"0.0%")))) | X16: =IF(A16="","",IF(AR16="","통과","제외: "&AR16)) | Y16: =IF(AND(ISNUMBER(G16),ISNUMBER(H16)),IF(G16>0,H16/G16,""),"") | Z16: =IF(AND(ISNUMBER(F16),ISNUMBER(G16)),IF(G16>0,F16/G16,""),"") | AA16: =IF(AND(ISNUMBER(J16),ISNUMBER(K16)),IF(AND(J16>0,K16>0),(J16/K16)^(1/3)-1,""),"") | AB16: =IF(AND(ISNUMBER(I16),ISNUMBER(L16),ISNUMBER(M16),ISNUMBER(N16)),IF((L16+M16-N16)>0,I16/(L16+M16-N16),""),"") | AC16: =IF(AND(ISNUMBER(O16),ISNUMBER(P16)),IF(AND(O16>0,P16>0),P16/O16-1,""),"") | AD16: =_xlfn.TEXTJOIN(", ",TRUE,IF(Z16="","ROE",""),IF(AA16="","매출성장률",""),IF(AB16="","이익수익률",""),IF(AC16="","12-1 수익률","")) | AE16: =IF(A16="","",IF(AR16<>"","점수 없음(거름망)",IF(AD16="","채점","점수 없음(결측: "&AD16&")"))) | AF16: =IF(AE16="채점",1,"") | AG16: =IF(AF16=1,Z16,"") | AH16: =IF(AF16=1,AA16,"") | AI16: =IF(AF16=1,AB16,"") | AJ16: =IF(AF16=1,AC16,"") | AK16: =IF(AF16=1,IF($B$3=1,50,(_xlfn.RANK.AVG(AG16,$AG$6:$AG$105,1)-1)/($B$3-1)*100),"") | AL16: =IF(AF16=1,IF($B$3=1,50,(_xlfn.RANK.AVG(AH16,$AH$6:$AH$105,1)-1)/($B$3-1)*100),"") | AM16: =IF(AF16=1,IF($B$3=1,50,(_xlfn.RANK.AVG(AI16,$AI$6:$AI$105,1)-1)/($B$3-1)*100),"") | AN16: =IF(AF16=1,IF($B$3=1,50,(_xlfn.RANK.AVG(AJ16,$AJ$6:$AJ$105,1)-1)/($B$3-1)*100),"") | AO16: =IF(AF16=1,ROUND(AVERAGE(AK16:AN16),6),"") | AP16: =IF(AND(AF16=1,C16<>"Y"),R16,"") | AQ16: =IF(AND(ISNUMBER(AP16),Q16="편입 후보"),AP16+(1000-ROW())/1000000,"") | AR16: =IF(A16="","",_xlfn.TEXTJOIN(", ",TRUE,IF(D16="Y","금융·리츠",""),IF(NOT(ISNUMBER(I16)),"영업이익 없음",IF(I16<=0,"영업적자","")),IF(OR(NOT(ISNUMBER(G16)),NOT(ISNUMBER(H16))),"부채비율 자료 없음",IF(G16<=0,"자본잠식",IF(H16/G16>'설정'!$B$8,"부채비율 초과",""))),IF(NOT(ISNUMBER(L16)),"시총 없음",IF(L16<'설정'!$B$9,"시총 미달",""))))
A17: K12 | B17: 예시통신 | E17: 2026-2Q | F17: 1100 | G17: 12000 | H17: 14000 | I17: 1800 | J17: 30000 | K17: 29000 | L17: 10000 | M17: 7000 | N17: 1000 | O17: 32000 | P17: 31000 | Q17: =IF(A17="","",IF(C17="Y",IF(AF17=1,IF(AND(R17<'설정'!$B$6,ISNUMBER($H$3)),IF(ROUND($H$3-R17,1)>='설정'!$B$7,"교체 제안 → "&$E$3&" ("&TEXT($H$3,"0.0")&")","보유 유지"),"보유 유지"),"보유 · 점수 없음"),IF(AF17=1,IF(R17>='설정'!$B$5,"편입 후보",""),""))) | R17: =IF(AF17=1,ROUND(IF($B$3=1,50,(_xlfn.RANK.AVG(AO17,$AO$6:$AO$105,1)-1)/($B$3-1)*100),1),"") | S17: =IF(A17="","",IF(AF17=1,_xlfn.TEXTJOIN(". ",TRUE,_xlfn.TEXTJOIN(", ",TRUE,IF(AK17>='설정'!$B$20,"수익성 높음",""),IF(AL17>='설정'!$B$20,"성장 빠름",""),IF(AM17>='설정'!$B$20,"가격 쌈",""),IF(AN17>='설정'!$B$20,"추세 좋음","")),_xlfn.TEXTJOIN(", ",TRUE,IF(AK17<'설정'!$B$21,"수익성 낮음",""),IF(AL17<'설정'!$B$21,"성장 느림",""),IF(AM17<'설정'!$B$21,"가격 비쌈",""),IF(AN17<'설정'!$B$21,"추세 약함","")),IF(_xlfn.TEXTJOIN("·",TRUE,IF(AND(AK17>='설정'!$B$21,AK17<'설정'!$B$20),"수익성",""),IF(AND(AL17>='설정'!$B$21,AL17<'설정'!$B$20),"성장",""),IF(AND(AM17>='설정'!$B$21,AM17<'설정'!$B$20),"가격",""),IF(AND(AN17>='설정'!$B$21,AN17<'설정'!$B$20),"추세",""))="","","보통: "&_xlfn.TEXTJOIN("·",TRUE,IF(AND(AK17>='설정'!$B$21,AK17<'설정'!$B$20),"수익성",""),IF(AND(AL17>='설정'!$B$21,AL17<'설정'!$B$20),"성장",""),IF(AND(AM17>='설정'!$B$21,AM17<'설정'!$B$20),"가격",""),IF(AND(AN17>='설정'!$B$21,AN17<'설정'!$B$20),"추세","")))),IF(X17="통과",AE17,X17))) | T17: =IF(AF17=1,TEXT(Z17,"0.0%")&" · 상위 "&TEXT(($B$3-_xlfn.RANK.AVG(AG17,$AG$6:$AG$105,1)+1)/$B$3*100,"0")&"%",IF(A17="","",IF(Z17="","결측",TEXT(Z17,"0.0%")))) | U17: =IF(AF17=1,TEXT(AA17,"0.0%")&" · 상위 "&TEXT(($B$3-_xlfn.RANK.AVG(AH17,$AH$6:$AH$105,1)+1)/$B$3*100,"0")&"%",IF(A17="","",IF(AA17="","결측",TEXT(AA17,"0.0%")))) | V17: =IF(AF17=1,TEXT(AB17,"0.0%")&" · 상위 "&TEXT(($B$3-_xlfn.RANK.AVG(AI17,$AI$6:$AI$105,1)+1)/$B$3*100,"0")&"%",IF(A17="","",IF(AB17="","결측",TEXT(AB17,"0.0%")))) | W17: =IF(AF17=1,TEXT(AC17,"0.0%")&" · 상위 "&TEXT(($B$3-_xlfn.RANK.AVG(AJ17,$AJ$6:$AJ$105,1)+1)/$B$3*100,"0")&"%",IF(A17="","",IF(AC17="","결측",TEXT(AC17,"0.0%")))) | X17: =IF(A17="","",IF(AR17="","통과","제외: "&AR17)) | Y17: =IF(AND(ISNUMBER(G17),ISNUMBER(H17)),IF(G17>0,H17/G17,""),"") | Z17: =IF(AND(ISNUMBER(F17),ISNUMBER(G17)),IF(G17>0,F17/G17,""),"") | AA17: =IF(AND(ISNUMBER(J17),ISNUMBER(K17)),IF(AND(J17>0,K17>0),(J17/K17)^(1/3)-1,""),"") | AB17: =IF(AND(ISNUMBER(I17),ISNUMBER(L17),ISNUMBER(M17),ISNUMBER(N17)),IF((L17+M17-N17)>0,I17/(L17+M17-N17),""),"") | AC17: =IF(AND(ISNUMBER(O17),ISNUMBER(P17)),IF(AND(O17>0,P17>0),P17/O17-1,""),"") | AD17: =_xlfn.TEXTJOIN(", ",TRUE,IF(Z17="","ROE",""),IF(AA17="","매출성장률",""),IF(AB17="","이익수익률",""),IF(AC17="","12-1 수익률","")) | AE17: =IF(A17="","",IF(AR17<>"","점수 없음(거름망)",IF(AD17="","채점","점수 없음(결측: "&AD17&")"))) | AF17: =IF(AE17="채점",1,"") | AG17: =IF(AF17=1,Z17,"") | AH17: =IF(AF17=1,AA17,"") | AI17: =IF(AF17=1,AB17,"") | AJ17: =IF(AF17=1,AC17,"") | AK17: =IF(AF17=1,IF($B$3=1,50,(_xlfn.RANK.AVG(AG17,$AG$6:$AG$105,1)-1)/($B$3-1)*100),"") | AL17: =IF(AF17=1,IF($B$3=1,50,(_xlfn.RANK.AVG(AH17,$AH$6:$AH$105,1)-1)/($B$3-1)*100),"") | AM17: =IF(AF17=1,IF($B$3=1,50,(_xlfn.RANK.AVG(AI17,$AI$6:$AI$105,1)-1)/($B$3-1)*100),"") | AN17: =IF(AF17=1,IF($B$3=1,50,(_xlfn.RANK.AVG(AJ17,$AJ$6:$AJ$105,1)-1)/($B$3-1)*100),"") | AO17: =IF(AF17=1,ROUND(AVERAGE(AK17:AN17),6),"") | AP17: =IF(AND(AF17=1,C17<>"Y"),R17,"") | AQ17: =IF(AND(ISNUMBER(AP17),Q17="편입 후보"),AP17+(1000-ROW())/1000000,"") | AR17: =IF(A17="","",_xlfn.TEXTJOIN(", ",TRUE,IF(D17="Y","금융·리츠",""),IF(NOT(ISNUMBER(I17)),"영업이익 없음",IF(I17<=0,"영업적자","")),IF(OR(NOT(ISNUMBER(G17)),NOT(ISNUMBER(H17))),"부채비율 자료 없음",IF(G17<=0,"자본잠식",IF(H17/G17>'설정'!$B$8,"부채비율 초과",""))),IF(NOT(ISNUMBER(L17)),"시총 없음",IF(L17<'설정'!$B$9,"시총 미달",""))))
Q18: =IF(A18="","",IF(C18="Y",IF(AF18=1,IF(AND(R18<'설정'!$B$6,ISNUMBER($H$3)),IF(ROUND($H$3-R18,1)>='설정'!$B$7,"교체 제안 → "&$E$3&" ("&TEXT($H$3,"0.0")&")","보유 유지"),"보유 유지"),"보유 · 점수 없음"),IF(AF18=1,IF(R18>='설정'!$B$5,"편입 후보",""),""))) | R18: =IF(AF18=1,ROUND(IF($B$3=1,50,(_xlfn.RANK.AVG(AO18,$AO$6:$AO$105,1)-1)/($B$3-1)*100),1),"") | S18: =IF(A18="","",IF(AF18=1,_xlfn.TEXTJOIN(". ",TRUE,_xlfn.TEXTJOIN(", ",TRUE,IF(AK18>='설정'!$B$20,"수익성 높음",""),IF(AL18>='설정'!$B$20,"성장 빠름",""),IF(AM18>='설정'!$B$20,"가격 쌈",""),IF(AN18>='설정'!$B$20,"추세 좋음","")),_xlfn.TEXTJOIN(", ",TRUE,IF(AK18<'설정'!$B$21,"수익성 낮음",""),IF(AL18<'설정'!$B$21,"성장 느림",""),IF(AM18<'설정'!$B$21,"가격 비쌈",""),IF(AN18<'설정'!$B$21,"추세 약함","")),IF(_xlfn.TEXTJOIN("·",TRUE,IF(AND(AK18>='설정'!$B$21,AK18<'설정'!$B$20),"수익성",""),IF(AND(AL18>='설정'!$B$21,AL18<'설정'!$B$20),"성장",""),IF(AND(AM18>='설정'!$B$21,AM18<'설정'!$B$20),"가격",""),IF(AND(AN18>='설정'!$B$21,AN18<'설정'!$B$20),"추세",""))="","","보통: "&_xlfn.TEXTJOIN("·",TRUE,IF(AND(AK18>='설정'!$B$21,AK18<'설정'!$B$20),"수익성",""),IF(AND(AL18>='설정'!$B$21,AL18<'설정'!$B$20),"성장",""),IF(AND(AM18>='설정'!$B$21,AM18<'설정'!$B$20),"가격",""),IF(AND(AN18>='설정'!$B$21,AN18<'설정'!$B$20),"추세","")))),IF(X18="통과",AE18,X18))) | T18: =IF(AF18=1,TEXT(Z18,"0.0%")&" · 상위 "&TEXT(($B$3-_xlfn.RANK.AVG(AG18,$AG$6:$AG$105,1)+1)/$B$3*100,"0")&"%",IF(A18="","",IF(Z18="","결측",TEXT(Z18,"0.0%")))) | U18: =IF(AF18=1,TEXT(AA18,"0.0%")&" · 상위 "&TEXT(($B$3-_xlfn.RANK.AVG(AH18,$AH$6:$AH$105,1)+1)/$B$3*100,"0")&"%",IF(A18="","",IF(AA18="","결측",TEXT(AA18,"0.0%")))) | V18: =IF(AF18=1,TEXT(AB18,"0.0%")&" · 상위 "&TEXT(($B$3-_xlfn.RANK.AVG(AI18,$AI$6:$AI$105,1)+1)/$B$3*100,"0")&"%",IF(A18="","",IF(AB18="","결측",TEXT(AB18,"0.0%")))) | W18: =IF(AF18=1,TEXT(AC18,"0.0%")&" · 상위 "&TEXT(($B$3-_xlfn.RANK.AVG(AJ18,$AJ$6:$AJ$105,1)+1)/$B$3*100,"0")&"%",IF(A18="","",IF(AC18="","결측",TEXT(AC18,"0.0%")))) | X18: =IF(A18="","",IF(AR18="","통과","제외: "&AR18)) | Y18: =IF(AND(ISNUMBER(G18),ISNUMBER(H18)),IF(G18>0,H18/G18,""),"") | Z18: =IF(AND(ISNUMBER(F18),ISNUMBER(G18)),IF(G18>0,F18/G18,""),"") | AA18: =IF(AND(ISNUMBER(J18),ISNUMBER(K18)),IF(AND(J18>0,K18>0),(J18/K18)^(1/3)-1,""),"") | AB18: =IF(AND(ISNUMBER(I18),ISNUMBER(L18),ISNUMBER(M18),ISNUMBER(N18)),IF((L18+M18-N18)>0,I18/(L18+M18-N18),""),"") | AC18: =IF(AND(ISNUMBER(O18),ISNUMBER(P18)),IF(AND(O18>0,P18>0),P18/O18-1,""),"") | AD18: =_xlfn.TEXTJOIN(", ",TRUE,IF(Z18="","ROE",""),IF(AA18="","매출성장률",""),IF(AB18="","이익수익률",""),IF(AC18="","12-1 수익률","")) | AE18: =IF(A18="","",IF(AR18<>"","점수 없음(거름망)",IF(AD18="","채점","점수 없음(결측: "&AD18&")"))) | AF18: =IF(AE18="채점",1,"") | AG18: =IF(AF18=1,Z18,"") | AH18: =IF(AF18=1,AA18,"") | AI18: =IF(AF18=1,AB18,"") | AJ18: =IF(AF18=1,AC18,"") | AK18: =IF(AF18=1,IF($B$3=1,50,(_xlfn.RANK.AVG(AG18,$AG$6:$AG$105,1)-1)/($B$3-1)*100),"") | AL18: =IF(AF18=1,IF($B$3=1,50,(_xlfn.RANK.AVG(AH18,$AH$6:$AH$105,1)-1)/($B$3-1)*100),"") | AM18: =IF(AF18=1,IF($B$3=1,50,(_xlfn.RANK.AVG(AI18,$AI$6:$AI$105,1)-1)/($B$3-1)*100),"") | AN18: =IF(AF18=1,IF($B$3=1,50,(_xlfn.RANK.AVG(AJ18,$AJ$6:$AJ$105,1)-1)/($B$3-1)*100),"") | AO18: =IF(AF18=1,ROUND(AVERAGE(AK18:AN18),6),"") | AP18: =IF(AND(AF18=1,C18<>"Y"),R18,"") | AQ18: =IF(AND(ISNUMBER(AP18),Q18="편입 후보"),AP18+(1000-ROW())/1000000,"") | AR18: =IF(A18="","",_xlfn.TEXTJOIN(", ",TRUE,IF(D18="Y","금융·리츠",""),IF(NOT(ISNUMBER(I18)),"영업이익 없음",IF(I18<=0,"영업적자","")),IF(OR(NOT(ISNUMBER(G18)),NOT(ISNUMBER(H18))),"부채비율 자료 없음",IF(G18<=0,"자본잠식",IF(H18/G18>'설정'!$B$8,"부채비율 초과",""))),IF(NOT(ISNUMBER(L18)),"시총 없음",IF(L18<'설정'!$B$9,"시총 미달",""))))
